2025-08-10 00:14:37,646 INFO: Database tables created successfully [in /home/sydney/HeliosOS/app/__init__.py:91]
2025-08-10 00:14:59,154 ERROR: Summarization failed: RetryError[<Future at 0x7f9b70632150 state=finished raised AIServiceError>] [in /home/sydney/HeliosOS/app/ai_client.py:96]
2025-08-10 00:14:59,211 ERROR: Failed to log AI interaction: The current Flask app is not registered with this 'SQLAlchemy' instance. Did you forget to call 'init_app', or did you create multiple 'SQLAlchemy' instances? [in /home/sydney/HeliosOS/app/ai_client.py:234]
2025-08-10 00:15:29,278 ERROR: Summarization failed: RetryError[<Future at 0x7f9b703628a0 state=finished raised AIServiceError>] [in /home/sydney/HeliosOS/app/ai_client.py:96]
2025-08-10 00:15:29,281 ERROR: Failed to log AI interaction: The current Flask app is not registered with this 'SQLAlchemy' instance. Did you forget to call 'init_app', or did you create multiple 'SQLAlchemy' instances? [in /home/sydney/HeliosOS/app/ai_client.py:234]
2025-08-10 00:15:59,303 ERROR: Summarization failed: RetryError[<Future at 0x7f9b70363b60 state=finished raised AIServiceError>] [in /home/sydney/HeliosOS/app/ai_client.py:96]
2025-08-10 00:15:59,305 ERROR: Failed to log AI interaction: The current Flask app is not registered with this 'SQLAlchemy' instance. Did you forget to call 'init_app', or did you create multiple 'SQLAlchemy' instances? [in /home/sydney/HeliosOS/app/ai_client.py:234]
2025-08-10 00:16:29,446 ERROR: Summarization failed: RetryError[<Future at 0x7f9b70398c50 state=finished raised AIServiceError>] [in /home/sydney/HeliosOS/app/ai_client.py:96]
2025-08-10 00:16:29,449 ERROR: Failed to log AI interaction: The current Flask app is not registered with this 'SQLAlchemy' instance. Did you forget to call 'init_app', or did you create multiple 'SQLAlchemy' instances? [in /home/sydney/HeliosOS/app/ai_client.py:234]
2025-08-10 00:16:59,253 ERROR: Summarization failed: RetryError[<Future at 0x7f9b70399f70 state=finished raised AIServiceError>] [in /home/sydney/HeliosOS/app/ai_client.py:96]
2025-08-10 00:16:59,254 ERROR: Failed to log AI interaction: The current Flask app is not registered with this 'SQLAlchemy' instance. Did you forget to call 'init_app', or did you create multiple 'SQLAlchemy' instances? [in /home/sydney/HeliosOS/app/ai_client.py:234]
2025-08-10 00:17:29,289 ERROR: Summarization failed: RetryError[<Future at 0x7f9b7039b020 state=finished raised AIServiceError>] [in /home/sydney/HeliosOS/app/ai_client.py:96]
2025-08-10 00:17:29,290 ERROR: Failed to log AI interaction: The current Flask app is not registered with this 'SQLAlchemy' instance. Did you forget to call 'init_app', or did you create multiple 'SQLAlchemy' instances? [in /home/sydney/HeliosOS/app/ai_client.py:234]
2025-08-10 00:17:59,296 ERROR: Summarization failed: RetryError[<Future at 0x7f9b703b8350 state=finished raised AIServiceError>] [in /home/sydney/HeliosOS/app/ai_client.py:96]
2025-08-10 00:17:59,298 ERROR: Failed to log AI interaction: The current Flask app is not registered with this 'SQLAlchemy' instance. Did you forget to call 'init_app', or did you create multiple 'SQLAlchemy' instances? [in /home/sydney/HeliosOS/app/ai_client.py:234]
2025-08-10 00:18:29,293 ERROR: Summarization failed: RetryError[<Future at 0x7f9b703b9400 state=finished raised AIServiceError>] [in /home/sydney/HeliosOS/app/ai_client.py:96]
2025-08-10 00:18:29,294 ERROR: Failed to log AI interaction: The current Flask app is not registered with this 'SQLAlchemy' instance. Did you forget to call 'init_app', or did you create multiple 'SQLAlchemy' instances? [in /home/sydney/HeliosOS/app/ai_client.py:234]
2025-08-10 00:19:05,291 ERROR: Summarization failed: RetryError[<Future at 0x7f9b703ba720 state=finished raised AIServiceError>] [in /home/sydney/HeliosOS/app/ai_client.py:96]
2025-08-10 00:19:05,293 ERROR: Failed to log AI interaction: The current Flask app is not registered with this 'SQLAlchemy' instance. Did you forget to call 'init_app', or did you create multiple 'SQLAlchemy' instances? [in /home/sydney/HeliosOS/app/ai_client.py:234]
2025-08-10 00:20:05,300 ERROR: Summarization failed: RetryError[<Future at 0x7f9b703bb830 state=finished raised AIServiceError>] [in /home/sydney/HeliosOS/app/ai_client.py:96]
2025-08-10 00:20:05,301 ERROR: Failed to log AI interaction: The current Flask app is not registered with this 'SQLAlchemy' instance. Did you forget to call 'init_app', or did you create multiple 'SQLAlchemy' instances? [in /home/sydney/HeliosOS/app/ai_client.py:234]
2025-08-10 00:21:05,294 ERROR: Summarization failed: RetryError[<Future at 0x7f9b701ecad0 state=finished raised AIServiceError>] [in /home/sydney/HeliosOS/app/ai_client.py:96]
2025-08-10 00:21:05,296 ERROR: Failed to log AI interaction: The current Flask app is not registered with this 'SQLAlchemy' instance. Did you forget to call 'init_app', or did you create multiple 'SQLAlchemy' instances? [in /home/sydney/HeliosOS/app/ai_client.py:234]
2025-08-10 00:22:05,294 ERROR: Summarization failed: RetryError[<Future at 0x7f9b701edbb0 state=finished raised AIServiceError>] [in /home/sydney/HeliosOS/app/ai_client.py:96]
2025-08-10 00:22:05,295 ERROR: Failed to log AI interaction: The current Flask app is not registered with this 'SQLAlchemy' instance. Did you forget to call 'init_app', or did you create multiple 'SQLAlchemy' instances? [in /home/sydney/HeliosOS/app/ai_client.py:234]
2025-08-10 00:23:05,289 ERROR: Summarization failed: RetryError[<Future at 0x7f9b701eef30 state=finished raised AIServiceError>] [in /home/sydney/HeliosOS/app/ai_client.py:96]
2025-08-10 00:23:05,291 ERROR: Failed to log AI interaction: The current Flask app is not registered with this 'SQLAlchemy' instance. Did you forget to call 'init_app', or did you create multiple 'SQLAlchemy' instances? [in /home/sydney/HeliosOS/app/ai_client.py:234]
2025-08-10 00:24:05,202 ERROR: Summarization failed: RetryError[<Future at 0x7f9b701effb0 state=finished raised AIServiceError>] [in /home/sydney/HeliosOS/app/ai_client.py:96]
2025-08-10 00:24:05,204 ERROR: Failed to log AI interaction: The current Flask app is not registered with this 'SQLAlchemy' instance. Did you forget to call 'init_app', or did you create multiple 'SQLAlchemy' instances? [in /home/sydney/HeliosOS/app/ai_client.py:234]
2025-08-10 00:25:05,283 ERROR: Summarization failed: RetryError[<Future at 0x7f9b70215370 state=finished raised AIServiceError>] [in /home/sydney/HeliosOS/app/ai_client.py:96]
2025-08-10 00:25:05,285 ERROR: Failed to log AI interaction: The current Flask app is not registered with this 'SQLAlchemy' instance. Did you forget to call 'init_app', or did you create multiple 'SQLAlchemy' instances? [in /home/sydney/HeliosOS/app/ai_client.py:234]
2025-08-10 00:26:05,304 ERROR: Summarization failed: RetryError[<Future at 0x7f9b70216510 state=finished raised AIServiceError>] [in /home/sydney/HeliosOS/app/ai_client.py:96]
2025-08-10 00:26:05,306 ERROR: Failed to log AI interaction: The current Flask app is not registered with this 'SQLAlchemy' instance. Did you forget to call 'init_app', or did you create multiple 'SQLAlchemy' instances? [in /home/sydney/HeliosOS/app/ai_client.py:234]
2025-08-10 00:27:05,289 ERROR: Summarization failed: RetryError[<Future at 0x7f9b702177d0 state=finished raised AIServiceError>] [in /home/sydney/HeliosOS/app/ai_client.py:96]
2025-08-10 00:27:05,292 ERROR: Failed to log AI interaction: The current Flask app is not registered with this 'SQLAlchemy' instance. Did you forget to call 'init_app', or did you create multiple 'SQLAlchemy' instances? [in /home/sydney/HeliosOS/app/ai_client.py:234]
2025-08-10 00:28:05,302 ERROR: Summarization failed: RetryError[<Future at 0x7f9b7023c920 state=finished raised AIServiceError>] [in /home/sydney/HeliosOS/app/ai_client.py:96]
2025-08-10 00:28:05,303 ERROR: Failed to log AI interaction: The current Flask app is not registered with this 'SQLAlchemy' instance. Did you forget to call 'init_app', or did you create multiple 'SQLAlchemy' instances? [in /home/sydney/HeliosOS/app/ai_client.py:234]
2025-08-10 00:29:05,293 ERROR: Summarization failed: RetryError[<Future at 0x7f9b7023dc40 state=finished raised AIServiceError>] [in /home/sydney/HeliosOS/app/ai_client.py:96]
2025-08-10 00:29:05,295 ERROR: Failed to log AI interaction: The current Flask app is not registered with this 'SQLAlchemy' instance. Did you forget to call 'init_app', or did you create multiple 'SQLAlchemy' instances? [in /home/sydney/HeliosOS/app/ai_client.py:234]
2025-08-10 00:30:05,283 ERROR: Summarization failed: RetryError[<Future at 0x7f9b7023edb0 state=finished raised AIServiceError>] [in /home/sydney/HeliosOS/app/ai_client.py:96]
2025-08-10 00:30:05,284 ERROR: Failed to log AI interaction: The current Flask app is not registered with this 'SQLAlchemy' instance. Did you forget to call 'init_app', or did you create multiple 'SQLAlchemy' instances? [in /home/sydney/HeliosOS/app/ai_client.py:234]
2025-08-10 00:31:05,293 ERROR: Summarization failed: RetryError[<Future at 0x7f9b7026c170 state=finished raised AIServiceError>] [in /home/sydney/HeliosOS/app/ai_client.py:96]
2025-08-10 00:31:05,295 ERROR: Failed to log AI interaction: The current Flask app is not registered with this 'SQLAlchemy' instance. Did you forget to call 'init_app', or did you create multiple 'SQLAlchemy' instances? [in /home/sydney/HeliosOS/app/ai_client.py:234]
2025-08-10 00:32:05,295 ERROR: Summarization failed: RetryError[<Future at 0x7f9b7026d3a0 state=finished raised AIServiceError>] [in /home/sydney/HeliosOS/app/ai_client.py:96]
2025-08-10 00:32:05,297 ERROR: Failed to log AI interaction: The current Flask app is not registered with this 'SQLAlchemy' instance. Did you forget to call 'init_app', or did you create multiple 'SQLAlchemy' instances? [in /home/sydney/HeliosOS/app/ai_client.py:234]
2025-08-10 00:33:05,289 ERROR: Summarization failed: RetryError[<Future at 0x7f9b7026e720 state=finished raised AIServiceError>] [in /home/sydney/HeliosOS/app/ai_client.py:96]
2025-08-10 00:33:05,290 ERROR: Failed to log AI interaction: The current Flask app is not registered with this 'SQLAlchemy' instance. Did you forget to call 'init_app', or did you create multiple 'SQLAlchemy' instances? [in /home/sydney/HeliosOS/app/ai_client.py:234]
2025-08-10 00:34:05,291 ERROR: Summarization failed: RetryError[<Future at 0x7f9b7026f8c0 state=finished raised AIServiceError>] [in /home/sydney/HeliosOS/app/ai_client.py:96]
2025-08-10 00:34:05,292 ERROR: Failed to log AI interaction: The current Flask app is not registered with this 'SQLAlchemy' instance. Did you forget to call 'init_app', or did you create multiple 'SQLAlchemy' instances? [in /home/sydney/HeliosOS/app/ai_client.py:234]
2025-08-10 00:35:05,282 ERROR: Summarization failed: RetryError[<Future at 0x7f9b7029cda0 state=finished raised AIServiceError>] [in /home/sydney/HeliosOS/app/ai_client.py:96]
2025-08-10 00:35:05,286 ERROR: Failed to log AI interaction: The current Flask app is not registered with this 'SQLAlchemy' instance. Did you forget to call 'init_app', or did you create multiple 'SQLAlchemy' instances? [in /home/sydney/HeliosOS/app/ai_client.py:234]
2025-08-10 00:36:05,291 ERROR: Summarization failed: RetryError[<Future at 0x7f9b7029e030 state=finished raised AIServiceError>] [in /home/sydney/HeliosOS/app/ai_client.py:96]
2025-08-10 00:36:05,292 ERROR: Failed to log AI interaction: The current Flask app is not registered with this 'SQLAlchemy' instance. Did you forget to call 'init_app', or did you create multiple 'SQLAlchemy' instances? [in /home/sydney/HeliosOS/app/ai_client.py:234]
2025-08-10 00:37:05,284 ERROR: Summarization failed: RetryError[<Future at 0x7f9b7029f440 state=finished raised AIServiceError>] [in /home/sydney/HeliosOS/app/ai_client.py:96]
2025-08-10 00:37:05,286 ERROR: Failed to log AI interaction: The current Flask app is not registered with this 'SQLAlchemy' instance. Did you forget to call 'init_app', or did you create multiple 'SQLAlchemy' instances? [in /home/sydney/HeliosOS/app/ai_client.py:234]
2025-08-10 00:38:05,306 ERROR: Summarization failed: RetryError[<Future at 0x7f9b702bc710 state=finished raised AIServiceError>] [in /home/sydney/HeliosOS/app/ai_client.py:96]
2025-08-10 00:38:05,307 ERROR: Failed to log AI interaction: The current Flask app is not registered with this 'SQLAlchemy' instance. Did you forget to call 'init_app', or did you create multiple 'SQLAlchemy' instances? [in /home/sydney/HeliosOS/app/ai_client.py:234]
2025-08-10 00:39:05,289 ERROR: Summarization failed: RetryError[<Future at 0x7f9b702bdac0 state=finished raised AIServiceError>] [in /home/sydney/HeliosOS/app/ai_client.py:96]
2025-08-10 00:39:05,292 ERROR: Failed to log AI interaction: The current Flask app is not registered with this 'SQLAlchemy' instance. Did you forget to call 'init_app', or did you create multiple 'SQLAlchemy' instances? [in /home/sydney/HeliosOS/app/ai_client.py:234]
2025-08-10 00:40:04,167 ERROR: Summarization failed: RetryError[<Future at 0x7f9b702becc0 state=finished raised AIServiceError>] [in /home/sydney/HeliosOS/app/ai_client.py:96]
2025-08-10 00:40:04,169 ERROR: Failed to log AI interaction: The current Flask app is not registered with this 'SQLAlchemy' instance. Did you forget to call 'init_app', or did you create multiple 'SQLAlchemy' instances? [in /home/sydney/HeliosOS/app/ai_client.py:234]
2025-08-10 00:40:29,289 ERROR: Summarization failed: RetryError[<Future at 0x7f9b700e0140 state=finished raised AIServiceError>] [in /home/sydney/HeliosOS/app/ai_client.py:96]
2025-08-10 00:40:29,298 ERROR: Failed to log AI interaction: The current Flask app is not registered with this 'SQLAlchemy' instance. Did you forget to call 'init_app', or did you create multiple 'SQLAlchemy' instances? [in /home/sydney/HeliosOS/app/ai_client.py:234]
2025-08-10 00:40:59,303 ERROR: Summarization failed: RetryError[<Future at 0x7f9b700e1340 state=finished raised AIServiceError>] [in /home/sydney/HeliosOS/app/ai_client.py:96]
2025-08-10 00:40:59,318 ERROR: Failed to log AI interaction: The current Flask app is not registered with this 'SQLAlchemy' instance. Did you forget to call 'init_app', or did you create multiple 'SQLAlchemy' instances? [in /home/sydney/HeliosOS/app/ai_client.py:234]
2025-08-10 00:42:00,356 ERROR: Summarization failed: RetryError[<Future at 0x7f9b700e2780 state=finished raised AIServiceError>] [in /home/sydney/HeliosOS/app/ai_client.py:96]
2025-08-10 00:42:00,360 ERROR: Failed to log AI interaction: The current Flask app is not registered with this 'SQLAlchemy' instance. Did you forget to call 'init_app', or did you create multiple 'SQLAlchemy' instances? [in /home/sydney/HeliosOS/app/ai_client.py:234]
2025-08-10 00:42:22,469 INFO: Database tables created successfully [in /home/sydney/HeliosOS/app/__init__.py:91]
2025-08-10 00:42:29,937 ERROR: Summarization failed: RetryError[<Future at 0x7f688afb22d0 state=finished raised AIServiceError>] [in /home/sydney/HeliosOS/app/ai_client.py:108]
2025-08-10 00:42:29,977 ERROR: Failed to log AI interaction: The current Flask app is not registered with this 'SQLAlchemy' instance. Did you forget to call 'init_app', or did you create multiple 'SQLAlchemy' instances? [in /home/sydney/HeliosOS/app/ai_client.py:265]
2025-08-10 00:42:32,644 ERROR: Summarization failed: RetryError[<Future at 0x7f688b0d1bb0 state=finished raised AIServiceError>] [in /home/sydney/HeliosOS/app/ai_client.py:108]
2025-08-10 00:42:32,646 ERROR: Failed to log AI interaction: The current Flask app is not registered with this 'SQLAlchemy' instance. Did you forget to call 'init_app', or did you create multiple 'SQLAlchemy' instances? [in /home/sydney/HeliosOS/app/ai_client.py:265]
2025-08-10 00:42:45,935 INFO: Database tables created successfully [in /home/sydney/HeliosOS/app/__init__.py:91]
2025-08-10 00:42:57,601 ERROR: Summarization failed: RetryError[<Future at 0x7ff7ca922e70 state=finished raised AIServiceError>] [in /home/sydney/HeliosOS/app/ai_client.py:108]
2025-08-10 00:42:57,632 ERROR: Failed to log AI interaction: The current Flask app is not registered with this 'SQLAlchemy' instance. Did you forget to call 'init_app', or did you create multiple 'SQLAlchemy' instances? [in /home/sydney/HeliosOS/app/ai_client.py:265]
2025-08-10 00:43:03,303 ERROR: Summarization failed: RetryError[<Future at 0x7ff7ca9527b0 state=finished raised AIServiceError>] [in /home/sydney/HeliosOS/app/ai_client.py:108]
2025-08-10 00:43:03,306 ERROR: Failed to log AI interaction: The current Flask app is not registered with this 'SQLAlchemy' instance. Did you forget to call 'init_app', or did you create multiple 'SQLAlchemy' instances? [in /home/sydney/HeliosOS/app/ai_client.py:265]
2025-08-10 00:43:28,292 ERROR: Summarization failed: RetryError[<Future at 0x7ff7ca953b30 state=finished raised AIServiceError>] [in /home/sydney/HeliosOS/app/ai_client.py:108]
2025-08-10 00:43:28,294 ERROR: Failed to log AI interaction: The current Flask app is not registered with this 'SQLAlchemy' instance. Did you forget to call 'init_app', or did you create multiple 'SQLAlchemy' instances? [in /home/sydney/HeliosOS/app/ai_client.py:265]
2025-08-10 00:43:33,359 ERROR: Summarization failed: RetryError[<Future at 0x7ff7ca988c20 state=finished raised AIServiceError>] [in /home/sydney/HeliosOS/app/ai_client.py:108]
2025-08-10 00:43:33,361 ERROR: Failed to log AI interaction: The current Flask app is not registered with this 'SQLAlchemy' instance. Did you forget to call 'init_app', or did you create multiple 'SQLAlchemy' instances? [in /home/sydney/HeliosOS/app/ai_client.py:265]
2025-08-10 00:44:09,652 ERROR: Failed to create database tables: (psycopg2.OperationalError) connection to server at "localhost" (127.0.0.1), port 5432 failed: FATAL:  password authentication failed for user "user"
connection to server at "localhost" (127.0.0.1), port 5432 failed: FATAL:  password authentication failed for user "user"

(Background on this error at: https://sqlalche.me/e/20/e3q8) [in /home/sydney/HeliosOS/app/__init__.py:93]
2025-08-10 00:44:23,012 ERROR: Database health check failed: (psycopg2.OperationalError) connection to server at "localhost" (127.0.0.1), port 5432 failed: FATAL:  password authentication failed for user "user"
connection to server at "localhost" (127.0.0.1), port 5432 failed: FATAL:  password authentication failed for user "user"

(Background on this error at: https://sqlalche.me/e/20/e3q8) [in /home/sydney/HeliosOS/app/routes.py:30]
2025-08-10 00:44:23,659 ERROR: Request failed for model facebook/bart-large-cnn: 401 Client Error: Unauthorized for url: https://api-inference.huggingface.co/models/facebook/bart-large-cnn [in /home/sydney/HeliosOS/app/ai_client.py:65]
2025-08-10 00:44:25,985 ERROR: Request failed for model facebook/bart-large-cnn: 401 Client Error: Unauthorized for url: https://api-inference.huggingface.co/models/facebook/bart-large-cnn [in /home/sydney/HeliosOS/app/ai_client.py:65]
2025-08-10 00:44:28,282 ERROR: Request failed for model facebook/bart-large-cnn: 401 Client Error: Unauthorized for url: https://api-inference.huggingface.co/models/facebook/bart-large-cnn [in /home/sydney/HeliosOS/app/ai_client.py:65]
2025-08-10 00:44:28,283 ERROR: Summarization failed: RetryError[<Future at 0x7f8800287b00 state=finished raised AIServiceError>] [in /home/sydney/HeliosOS/app/ai_client.py:108]
2025-08-10 00:44:28,305 ERROR: Failed to log AI interaction: The current Flask app is not registered with this 'SQLAlchemy' instance. Did you forget to call 'init_app', or did you create multiple 'SQLAlchemy' instances? [in /home/sydney/HeliosOS/app/ai_client.py:265]
2025-08-10 00:44:28,379 ERROR: Database health check failed: (psycopg2.OperationalError) connection to server at "localhost" (127.0.0.1), port 5432 failed: FATAL:  password authentication failed for user "user"
connection to server at "localhost" (127.0.0.1), port 5432 failed: FATAL:  password authentication failed for user "user"

(Background on this error at: https://sqlalche.me/e/20/e3q8) [in /home/sydney/HeliosOS/app/routes.py:30]
2025-08-10 00:44:28,859 ERROR: Request failed for model facebook/bart-large-cnn: 401 Client Error: Unauthorized for url: https://api-inference.huggingface.co/models/facebook/bart-large-cnn [in /home/sydney/HeliosOS/app/ai_client.py:65]
2025-08-10 00:44:29,295 ERROR: Database health check failed: (psycopg2.OperationalError) connection to server at "localhost" (127.0.0.1), port 5432 failed: FATAL:  password authentication failed for user "user"
connection to server at "localhost" (127.0.0.1), port 5432 failed: FATAL:  password authentication failed for user "user"

(Background on this error at: https://sqlalche.me/e/20/e3q8) [in /home/sydney/HeliosOS/app/routes.py:30]
2025-08-10 00:44:29,847 ERROR: Request failed for model facebook/bart-large-cnn: 401 Client Error: Unauthorized for url: https://api-inference.huggingface.co/models/facebook/bart-large-cnn [in /home/sydney/HeliosOS/app/ai_client.py:65]
2025-08-10 00:44:31,828 ERROR: Request failed for model facebook/bart-large-cnn: 401 Client Error: Unauthorized for url: https://api-inference.huggingface.co/models/facebook/bart-large-cnn [in /home/sydney/HeliosOS/app/ai_client.py:65]
2025-08-10 00:44:34,099 ERROR: Request failed for model facebook/bart-large-cnn: 401 Client Error: Unauthorized for url: https://api-inference.huggingface.co/models/facebook/bart-large-cnn [in /home/sydney/HeliosOS/app/ai_client.py:65]
2025-08-10 00:53:53,970 ERROR: Failed to create database tables: (psycopg2.OperationalError) connection to server at "localhost" (127.0.0.1), port 5432 failed: FATAL:  password authentication failed for user "sydney"
connection to server at "localhost" (127.0.0.1), port 5432 failed: FATAL:  password authentication failed for user "sydney"

(Background on this error at: https://sqlalche.me/e/20/e3q8) [in /home/sydney/HeliosOS/app/__init__.py:93]
2025-08-10 00:53:58,975 ERROR: Database health check failed: (psycopg2.OperationalError) connection to server at "localhost" (127.0.0.1), port 5432 failed: FATAL:  password authentication failed for user "sydney"
connection to server at "localhost" (127.0.0.1), port 5432 failed: FATAL:  password authentication failed for user "sydney"

(Background on this error at: https://sqlalche.me/e/20/e3q8) [in /home/sydney/HeliosOS/app/routes.py:30]
2025-08-10 00:54:01,332 ERROR: Database health check failed: (psycopg2.OperationalError) connection to server at "localhost" (127.0.0.1), port 5432 failed: FATAL:  password authentication failed for user "sydney"
connection to server at "localhost" (127.0.0.1), port 5432 failed: FATAL:  password authentication failed for user "sydney"

(Background on this error at: https://sqlalche.me/e/20/e3q8) [in /home/sydney/HeliosOS/app/routes.py:30]
2025-08-10 00:54:08,655 ERROR: Request failed for model facebook/bart-large-cnn: 401 Client Error: Unauthorized for url: https://api-inference.huggingface.co/models/facebook/bart-large-cnn [in /home/sydney/HeliosOS/app/ai_client.py:65]
2025-08-10 00:54:08,716 ERROR: Request failed for model facebook/bart-large-cnn: 401 Client Error: Unauthorized for url: https://api-inference.huggingface.co/models/facebook/bart-large-cnn [in /home/sydney/HeliosOS/app/ai_client.py:65]
2025-08-10 00:54:12,877 ERROR: Request failed for model facebook/bart-large-cnn: 401 Client Error: Unauthorized for url: https://api-inference.huggingface.co/models/facebook/bart-large-cnn [in /home/sydney/HeliosOS/app/ai_client.py:65]
2025-08-10 00:54:12,993 ERROR: Request failed for model facebook/bart-large-cnn: 401 Client Error: Unauthorized for url: https://api-inference.huggingface.co/models/facebook/bart-large-cnn [in /home/sydney/HeliosOS/app/ai_client.py:65]
2025-08-10 00:54:25,044 ERROR: Request failed for model facebook/bart-large-cnn: 401 Client Error: Unauthorized for url: https://api-inference.huggingface.co/models/facebook/bart-large-cnn [in /home/sydney/HeliosOS/app/ai_client.py:65]
2025-08-10 00:54:25,046 ERROR: Summarization failed: RetryError[<Future at 0x7f77c9a18620 state=finished raised AIServiceError>] [in /home/sydney/HeliosOS/app/ai_client.py:108]
2025-08-10 00:54:25,047 WARNING: Database not available, skipping logging: The current Flask app is not registered with this 'SQLAlchemy' instance. Did you forget to call 'init_app', or did you create multiple 'SQLAlchemy' instances? [in /home/sydney/HeliosOS/app/ai_client.py:242]
2025-08-10 00:54:25,064 ERROR: Request failed for model facebook/bart-large-cnn: 401 Client Error: Unauthorized for url: https://api-inference.huggingface.co/models/facebook/bart-large-cnn [in /home/sydney/HeliosOS/app/ai_client.py:65]
2025-08-10 00:54:25,065 ERROR: Summarization failed: RetryError[<Future at 0x7f77c7b14290 state=finished raised AIServiceError>] [in /home/sydney/HeliosOS/app/ai_client.py:108]
2025-08-10 00:54:25,065 WARNING: Database not available, skipping logging: The current Flask app is not registered with this 'SQLAlchemy' instance. Did you forget to call 'init_app', or did you create multiple 'SQLAlchemy' instances? [in /home/sydney/HeliosOS/app/ai_client.py:242]
2025-08-10 00:54:29,201 ERROR: Database health check failed: (psycopg2.OperationalError) connection to server at "localhost" (127.0.0.1), port 5432 failed: FATAL:  password authentication failed for user "sydney"
connection to server at "localhost" (127.0.0.1), port 5432 failed: FATAL:  password authentication failed for user "sydney"

(Background on this error at: https://sqlalche.me/e/20/e3q8) [in /home/sydney/HeliosOS/app/routes.py:30]
2025-08-10 00:54:29,308 ERROR: Database health check failed: (psycopg2.OperationalError) connection to server at "localhost" (127.0.0.1), port 5432 failed: FATAL:  password authentication failed for user "sydney"
connection to server at "localhost" (127.0.0.1), port 5432 failed: FATAL:  password authentication failed for user "sydney"

(Background on this error at: https://sqlalche.me/e/20/e3q8) [in /home/sydney/HeliosOS/app/routes.py:30]
2025-08-10 00:54:39,214 ERROR: Request failed for model facebook/bart-large-cnn: HTTPSConnectionPool(host='api-inference.huggingface.co', port=443): Max retries exceeded with url: /models/facebook/bart-large-cnn (Caused by NameResolutionError("<urllib3.connection.HTTPSConnection object at 0x7f77c7bb6690>: Failed to resolve 'api-inference.huggingface.co' ([Errno -3] Temporary failure in name resolution)")) [in /home/sydney/HeliosOS/app/ai_client.py:65]
2025-08-10 00:54:39,318 ERROR: Request failed for model facebook/bart-large-cnn: HTTPSConnectionPool(host='api-inference.huggingface.co', port=443): Max retries exceeded with url: /models/facebook/bart-large-cnn (Caused by NameResolutionError("<urllib3.connection.HTTPSConnection object at 0x7f77c7bb5d00>: Failed to resolve 'api-inference.huggingface.co' ([Errno -3] Temporary failure in name resolution)")) [in /home/sydney/HeliosOS/app/ai_client.py:65]
2025-08-10 00:55:19,390 ERROR: Database health check failed: (psycopg2.OperationalError) connection to server at "localhost" (127.0.0.1), port 5432 failed: FATAL:  password authentication failed for user "sydney"
connection to server at "localhost" (127.0.0.1), port 5432 failed: FATAL:  password authentication failed for user "sydney"

(Background on this error at: https://sqlalche.me/e/20/e3q8) [in /home/sydney/HeliosOS/app/routes.py:30]
2025-08-10 00:55:19,427 ERROR: Database health check failed: (psycopg2.OperationalError) connection to server at "localhost" (127.0.0.1), port 5432 failed: FATAL:  password authentication failed for user "sydney"
connection to server at "localhost" (127.0.0.1), port 5432 failed: FATAL:  password authentication failed for user "sydney"

(Background on this error at: https://sqlalche.me/e/20/e3q8) [in /home/sydney/HeliosOS/app/routes.py:30]
2025-08-10 01:04:47,532 ERROR: Failed to create database tables: (psycopg2.OperationalError) connection to server at "localhost" (127.0.0.1), port 5432 failed: FATAL:  password authentication failed for user "sydney"
connection to server at "localhost" (127.0.0.1), port 5432 failed: FATAL:  password authentication failed for user "sydney"

(Background on this error at: https://sqlalche.me/e/20/e3q8) [in /home/sydney/HeliosOS/app/__init__.py:93]
2025-08-10 01:05:01,424 ERROR: Database health check failed: (psycopg2.OperationalError) connection to server at "localhost" (127.0.0.1), port 5432 failed: FATAL:  password authentication failed for user "sydney"
connection to server at "localhost" (127.0.0.1), port 5432 failed: FATAL:  password authentication failed for user "sydney"

(Background on this error at: https://sqlalche.me/e/20/e3q8) [in /home/sydney/HeliosOS/app/routes.py:30]
2025-08-10 01:05:02,234 ERROR: Request failed for model facebook/bart-large-cnn: 401 Client Error: Unauthorized for url: https://api-inference.huggingface.co/models/facebook/bart-large-cnn [in /home/sydney/HeliosOS/app/ai_client.py:65]
2025-08-10 01:05:04,803 ERROR: Request failed for model facebook/bart-large-cnn: 401 Client Error: Unauthorized for url: https://api-inference.huggingface.co/models/facebook/bart-large-cnn [in /home/sydney/HeliosOS/app/ai_client.py:65]
2025-08-10 01:05:07,055 ERROR: Request failed for model facebook/bart-large-cnn: 401 Client Error: Unauthorized for url: https://api-inference.huggingface.co/models/facebook/bart-large-cnn [in /home/sydney/HeliosOS/app/ai_client.py:65]
2025-08-10 01:05:07,055 ERROR: Summarization failed: RetryError[<Future at 0x7fa603b89430 state=finished raised AIServiceError>] [in /home/sydney/HeliosOS/app/ai_client.py:108]
2025-08-10 01:05:07,056 WARNING: Database not available, skipping logging: The current Flask app is not registered with this 'SQLAlchemy' instance. Did you forget to call 'init_app', or did you create multiple 'SQLAlchemy' instances? [in /home/sydney/HeliosOS/app/ai_client.py:242]
2025-08-10 01:06:01,395 ERROR: Database health check failed: (psycopg2.OperationalError) connection to server at "localhost" (127.0.0.1), port 5432 failed: FATAL:  password authentication failed for user "sydney"
connection to server at "localhost" (127.0.0.1), port 5432 failed: FATAL:  password authentication failed for user "sydney"

(Background on this error at: https://sqlalche.me/e/20/e3q8) [in /home/sydney/HeliosOS/app/routes.py:30]
2025-08-10 01:06:01,728 ERROR: Request failed for model facebook/bart-large-cnn: 401 Client Error: Unauthorized for url: https://api-inference.huggingface.co/models/facebook/bart-large-cnn [in /home/sydney/HeliosOS/app/ai_client.py:65]
2025-08-10 01:06:03,965 ERROR: Request failed for model facebook/bart-large-cnn: 401 Client Error: Unauthorized for url: https://api-inference.huggingface.co/models/facebook/bart-large-cnn [in /home/sydney/HeliosOS/app/ai_client.py:65]
2025-08-10 01:06:06,210 ERROR: Request failed for model facebook/bart-large-cnn: 401 Client Error: Unauthorized for url: https://api-inference.huggingface.co/models/facebook/bart-large-cnn [in /home/sydney/HeliosOS/app/ai_client.py:65]
2025-08-10 01:06:06,211 ERROR: Summarization failed: RetryError[<Future at 0x7fa602b070e0 state=finished raised AIServiceError>] [in /home/sydney/HeliosOS/app/ai_client.py:108]
2025-08-10 01:06:06,211 WARNING: Database not available, skipping logging: The current Flask app is not registered with this 'SQLAlchemy' instance. Did you forget to call 'init_app', or did you create multiple 'SQLAlchemy' instances? [in /home/sydney/HeliosOS/app/ai_client.py:242]
2025-08-10 01:07:01,305 ERROR: Database health check failed: (psycopg2.OperationalError) connection to server at "localhost" (127.0.0.1), port 5432 failed: FATAL:  password authentication failed for user "sydney"
connection to server at "localhost" (127.0.0.1), port 5432 failed: FATAL:  password authentication failed for user "sydney"

(Background on this error at: https://sqlalche.me/e/20/e3q8) [in /home/sydney/HeliosOS/app/routes.py:30]
2025-08-10 01:07:01,902 ERROR: Request failed for model facebook/bart-large-cnn: 401 Client Error: Unauthorized for url: https://api-inference.huggingface.co/models/facebook/bart-large-cnn [in /home/sydney/HeliosOS/app/ai_client.py:65]
2025-08-10 01:07:08,091 ERROR: Failed to create database tables: (psycopg2.OperationalError) connection to server at "localhost" (127.0.0.1), port 5432 failed: FATAL:  password authentication failed for user "sydney"
connection to server at "localhost" (127.0.0.1), port 5432 failed: FATAL:  password authentication failed for user "sydney"

(Background on this error at: https://sqlalche.me/e/20/e3q8) [in /home/sydney/HeliosOS/app/__init__.py:93]
2025-08-10 01:11:39,232 ERROR: Failed to create database tables: (psycopg2.OperationalError) connection to server at "localhost" (127.0.0.1), port 5432 failed: FATAL:  password authentication failed for user "sydney"
connection to server at "localhost" (127.0.0.1), port 5432 failed: FATAL:  password authentication failed for user "sydney"

(Background on this error at: https://sqlalche.me/e/20/e3q8) [in /home/sydney/HeliosOS/app/__init__.py:99]
2025-08-10 01:16:15,411 INFO: Database tables created successfully [in /home/sydney/HeliosOS/app/__init__.py:97]
2025-08-10 01:16:21,991 ERROR: Request failed for model facebook/bart-large-cnn: 401 Client Error: Unauthorized for url: https://api-inference.huggingface.co/models/facebook/bart-large-cnn [in /home/sydney/HeliosOS/app/ai_client.py:65]
2025-08-10 01:16:24,270 ERROR: Request failed for model facebook/bart-large-cnn: 401 Client Error: Unauthorized for url: https://api-inference.huggingface.co/models/facebook/bart-large-cnn [in /home/sydney/HeliosOS/app/ai_client.py:65]
2025-08-10 01:16:26,523 ERROR: Request failed for model facebook/bart-large-cnn: 401 Client Error: Unauthorized for url: https://api-inference.huggingface.co/models/facebook/bart-large-cnn [in /home/sydney/HeliosOS/app/ai_client.py:65]
2025-08-10 01:16:26,524 ERROR: Summarization failed: RetryError[<Future at 0x7f465d111970 state=finished raised AIServiceError>] [in /home/sydney/HeliosOS/app/ai_client.py:108]
2025-08-10 01:16:26,525 WARNING: Database not available, skipping logging: The current Flask app is not registered with this 'SQLAlchemy' instance. Did you forget to call 'init_app', or did you create multiple 'SQLAlchemy' instances? [in /home/sydney/HeliosOS/app/ai_client.py:242]
2025-08-10 01:16:51,530 ERROR: Request failed for model facebook/bart-large-cnn: 401 Client Error: Unauthorized for url: https://api-inference.huggingface.co/models/facebook/bart-large-cnn [in /home/sydney/HeliosOS/app/ai_client.py:65]
2025-08-10 01:16:53,775 ERROR: Request failed for model facebook/bart-large-cnn: 401 Client Error: Unauthorized for url: https://api-inference.huggingface.co/models/facebook/bart-large-cnn [in /home/sydney/HeliosOS/app/ai_client.py:65]
2025-08-10 01:16:56,012 ERROR: Request failed for model facebook/bart-large-cnn: 401 Client Error: Unauthorized for url: https://api-inference.huggingface.co/models/facebook/bart-large-cnn [in /home/sydney/HeliosOS/app/ai_client.py:65]
2025-08-10 01:16:56,013 ERROR: Summarization failed: RetryError[<Future at 0x7f465b1954f0 state=finished raised AIServiceError>] [in /home/sydney/HeliosOS/app/ai_client.py:108]
2025-08-10 01:16:56,013 WARNING: Database not available, skipping logging: The current Flask app is not registered with this 'SQLAlchemy' instance. Did you forget to call 'init_app', or did you create multiple 'SQLAlchemy' instances? [in /home/sydney/HeliosOS/app/ai_client.py:242]
2025-08-10 01:17:01,545 ERROR: Request failed for model facebook/bart-large-cnn: 401 Client Error: Unauthorized for url: https://api-inference.huggingface.co/models/facebook/bart-large-cnn [in /home/sydney/HeliosOS/app/ai_client.py:65]
2025-08-10 01:17:03,786 ERROR: Request failed for model facebook/bart-large-cnn: 401 Client Error: Unauthorized for url: https://api-inference.huggingface.co/models/facebook/bart-large-cnn [in /home/sydney/HeliosOS/app/ai_client.py:65]
2025-08-10 01:17:06,021 ERROR: Request failed for model facebook/bart-large-cnn: 401 Client Error: Unauthorized for url: https://api-inference.huggingface.co/models/facebook/bart-large-cnn [in /home/sydney/HeliosOS/app/ai_client.py:65]
2025-08-10 01:17:06,022 ERROR: Summarization failed: RetryError[<Future at 0x7f465b1969c0 state=finished raised AIServiceError>] [in /home/sydney/HeliosOS/app/ai_client.py:108]
2025-08-10 01:17:06,023 WARNING: Database not available, skipping logging: The current Flask app is not registered with this 'SQLAlchemy' instance. Did you forget to call 'init_app', or did you create multiple 'SQLAlchemy' instances? [in /home/sydney/HeliosOS/app/ai_client.py:242]
2025-08-10 01:17:21,903 ERROR: Request failed for model facebook/bart-large-cnn: 401 Client Error: Unauthorized for url: https://api-inference.huggingface.co/models/facebook/bart-large-cnn [in /home/sydney/HeliosOS/app/ai_client.py:65]
2025-08-10 01:17:24,168 ERROR: Request failed for model facebook/bart-large-cnn: 401 Client Error: Unauthorized for url: https://api-inference.huggingface.co/models/facebook/bart-large-cnn [in /home/sydney/HeliosOS/app/ai_client.py:65]
2025-08-10 01:17:26,485 ERROR: Request failed for model facebook/bart-large-cnn: 401 Client Error: Unauthorized for url: https://api-inference.huggingface.co/models/facebook/bart-large-cnn [in /home/sydney/HeliosOS/app/ai_client.py:65]
2025-08-10 01:17:26,486 ERROR: Summarization failed: RetryError[<Future at 0x7f465b1968d0 state=finished raised AIServiceError>] [in /home/sydney/HeliosOS/app/ai_client.py:108]
2025-08-10 01:17:26,486 WARNING: Database not available, skipping logging: The current Flask app is not registered with this 'SQLAlchemy' instance. Did you forget to call 'init_app', or did you create multiple 'SQLAlchemy' instances? [in /home/sydney/HeliosOS/app/ai_client.py:242]
2025-08-10 01:17:51,601 ERROR: Request failed for model facebook/bart-large-cnn: 401 Client Error: Unauthorized for url: https://api-inference.huggingface.co/models/facebook/bart-large-cnn [in /home/sydney/HeliosOS/app/ai_client.py:65]
2025-08-10 01:17:54,272 ERROR: Request failed for model facebook/bart-large-cnn: 401 Client Error: Unauthorized for url: https://api-inference.huggingface.co/models/facebook/bart-large-cnn [in /home/sydney/HeliosOS/app/ai_client.py:65]
2025-08-10 01:17:56,515 ERROR: Request failed for model facebook/bart-large-cnn: 401 Client Error: Unauthorized for url: https://api-inference.huggingface.co/models/facebook/bart-large-cnn [in /home/sydney/HeliosOS/app/ai_client.py:65]
2025-08-10 01:17:56,515 ERROR: Summarization failed: RetryError[<Future at 0x7f465b194530 state=finished raised AIServiceError>] [in /home/sydney/HeliosOS/app/ai_client.py:108]
2025-08-10 01:17:56,516 WARNING: Database not available, skipping logging: The current Flask app is not registered with this 'SQLAlchemy' instance. Did you forget to call 'init_app', or did you create multiple 'SQLAlchemy' instances? [in /home/sydney/HeliosOS/app/ai_client.py:242]
2025-08-10 01:18:01,681 ERROR: Request failed for model facebook/bart-large-cnn: 401 Client Error: Unauthorized for url: https://api-inference.huggingface.co/models/facebook/bart-large-cnn [in /home/sydney/HeliosOS/app/ai_client.py:65]
2025-08-10 01:18:03,917 ERROR: Request failed for model facebook/bart-large-cnn: 401 Client Error: Unauthorized for url: https://api-inference.huggingface.co/models/facebook/bart-large-cnn [in /home/sydney/HeliosOS/app/ai_client.py:65]
2025-08-10 01:18:06,154 ERROR: Request failed for model facebook/bart-large-cnn: 401 Client Error: Unauthorized for url: https://api-inference.huggingface.co/models/facebook/bart-large-cnn [in /home/sydney/HeliosOS/app/ai_client.py:65]
2025-08-10 01:18:06,155 ERROR: Summarization failed: RetryError[<Future at 0x7f465b947d10 state=finished raised AIServiceError>] [in /home/sydney/HeliosOS/app/ai_client.py:108]
2025-08-10 01:18:06,156 WARNING: Database not available, skipping logging: The current Flask app is not registered with this 'SQLAlchemy' instance. Did you forget to call 'init_app', or did you create multiple 'SQLAlchemy' instances? [in /home/sydney/HeliosOS/app/ai_client.py:242]
2025-08-10 01:18:21,803 ERROR: Request failed for model facebook/bart-large-cnn: 401 Client Error: Unauthorized for url: https://api-inference.huggingface.co/models/facebook/bart-large-cnn [in /home/sydney/HeliosOS/app/ai_client.py:65]
2025-08-10 01:18:24,055 ERROR: Request failed for model facebook/bart-large-cnn: 401 Client Error: Unauthorized for url: https://api-inference.huggingface.co/models/facebook/bart-large-cnn [in /home/sydney/HeliosOS/app/ai_client.py:65]
2025-08-10 01:18:26,296 ERROR: Request failed for model facebook/bart-large-cnn: 401 Client Error: Unauthorized for url: https://api-inference.huggingface.co/models/facebook/bart-large-cnn [in /home/sydney/HeliosOS/app/ai_client.py:65]
2025-08-10 01:18:26,297 ERROR: Summarization failed: RetryError[<Future at 0x7f465b195fd0 state=finished raised AIServiceError>] [in /home/sydney/HeliosOS/app/ai_client.py:108]
2025-08-10 01:18:26,298 WARNING: Database not available, skipping logging: The current Flask app is not registered with this 'SQLAlchemy' instance. Did you forget to call 'init_app', or did you create multiple 'SQLAlchemy' instances? [in /home/sydney/HeliosOS/app/ai_client.py:242]
2025-08-10 01:18:51,791 ERROR: Request failed for model facebook/bart-large-cnn: 401 Client Error: Unauthorized for url: https://api-inference.huggingface.co/models/facebook/bart-large-cnn [in /home/sydney/HeliosOS/app/ai_client.py:65]
2025-08-10 01:18:54,025 ERROR: Request failed for model facebook/bart-large-cnn: 401 Client Error: Unauthorized for url: https://api-inference.huggingface.co/models/facebook/bart-large-cnn [in /home/sydney/HeliosOS/app/ai_client.py:65]
2025-08-10 01:18:56,273 ERROR: Request failed for model facebook/bart-large-cnn: 401 Client Error: Unauthorized for url: https://api-inference.huggingface.co/models/facebook/bart-large-cnn [in /home/sydney/HeliosOS/app/ai_client.py:65]
2025-08-10 01:18:56,274 ERROR: Summarization failed: RetryError[<Future at 0x7f465b195af0 state=finished raised AIServiceError>] [in /home/sydney/HeliosOS/app/ai_client.py:108]
2025-08-10 01:18:56,274 WARNING: Database not available, skipping logging: The current Flask app is not registered with this 'SQLAlchemy' instance. Did you forget to call 'init_app', or did you create multiple 'SQLAlchemy' instances? [in /home/sydney/HeliosOS/app/ai_client.py:242]
2025-08-10 01:19:02,046 ERROR: Request failed for model facebook/bart-large-cnn: 401 Client Error: Unauthorized for url: https://api-inference.huggingface.co/models/facebook/bart-large-cnn [in /home/sydney/HeliosOS/app/ai_client.py:65]
2025-08-10 01:19:04,416 ERROR: Request failed for model facebook/bart-large-cnn: 401 Client Error: Unauthorized for url: https://api-inference.huggingface.co/models/facebook/bart-large-cnn [in /home/sydney/HeliosOS/app/ai_client.py:65]
2025-08-10 01:19:06,777 ERROR: Request failed for model facebook/bart-large-cnn: 401 Client Error: Unauthorized for url: https://api-inference.huggingface.co/models/facebook/bart-large-cnn [in /home/sydney/HeliosOS/app/ai_client.py:65]
2025-08-10 01:19:06,777 ERROR: Summarization failed: RetryError[<Future at 0x7f465b196030 state=finished raised AIServiceError>] [in /home/sydney/HeliosOS/app/ai_client.py:108]
2025-08-10 01:19:06,777 WARNING: Database not available, skipping logging: The current Flask app is not registered with this 'SQLAlchemy' instance. Did you forget to call 'init_app', or did you create multiple 'SQLAlchemy' instances? [in /home/sydney/HeliosOS/app/ai_client.py:242]
2025-08-10 01:19:21,677 ERROR: Request failed for model facebook/bart-large-cnn: 401 Client Error: Unauthorized for url: https://api-inference.huggingface.co/models/facebook/bart-large-cnn [in /home/sydney/HeliosOS/app/ai_client.py:65]
2025-08-10 01:19:23,915 ERROR: Request failed for model facebook/bart-large-cnn: 401 Client Error: Unauthorized for url: https://api-inference.huggingface.co/models/facebook/bart-large-cnn [in /home/sydney/HeliosOS/app/ai_client.py:65]
2025-08-10 01:19:26,165 ERROR: Request failed for model facebook/bart-large-cnn: 401 Client Error: Unauthorized for url: https://api-inference.huggingface.co/models/facebook/bart-large-cnn [in /home/sydney/HeliosOS/app/ai_client.py:65]
2025-08-10 01:19:26,165 ERROR: Summarization failed: RetryError[<Future at 0x7f465b197020 state=finished raised AIServiceError>] [in /home/sydney/HeliosOS/app/ai_client.py:108]
2025-08-10 01:19:26,166 WARNING: Database not available, skipping logging: The current Flask app is not registered with this 'SQLAlchemy' instance. Did you forget to call 'init_app', or did you create multiple 'SQLAlchemy' instances? [in /home/sydney/HeliosOS/app/ai_client.py:242]
2025-08-10 01:20:03,761 ERROR: Request failed for model facebook/bart-large-cnn: 401 Client Error: Unauthorized for url: https://api-inference.huggingface.co/models/facebook/bart-large-cnn [in /home/sydney/HeliosOS/app/ai_client.py:65]
2025-08-10 01:20:03,768 ERROR: Request failed for model facebook/bart-large-cnn: 401 Client Error: Unauthorized for url: https://api-inference.huggingface.co/models/facebook/bart-large-cnn [in /home/sydney/HeliosOS/app/ai_client.py:65]
2025-08-10 01:20:06,006 ERROR: Request failed for model facebook/bart-large-cnn: 401 Client Error: Unauthorized for url: https://api-inference.huggingface.co/models/facebook/bart-large-cnn [in /home/sydney/HeliosOS/app/ai_client.py:65]
2025-08-10 01:20:06,018 ERROR: Request failed for model facebook/bart-large-cnn: 401 Client Error: Unauthorized for url: https://api-inference.huggingface.co/models/facebook/bart-large-cnn [in /home/sydney/HeliosOS/app/ai_client.py:65]
2025-08-10 01:20:08,269 ERROR: Request failed for model facebook/bart-large-cnn: 401 Client Error: Unauthorized for url: https://api-inference.huggingface.co/models/facebook/bart-large-cnn [in /home/sydney/HeliosOS/app/ai_client.py:65]
2025-08-10 01:20:08,270 ERROR: Summarization failed: RetryError[<Future at 0x7f465b197d40 state=finished raised AIServiceError>] [in /home/sydney/HeliosOS/app/ai_client.py:108]
2025-08-10 01:20:08,270 WARNING: Database not available, skipping logging: The current Flask app is not registered with this 'SQLAlchemy' instance. Did you forget to call 'init_app', or did you create multiple 'SQLAlchemy' instances? [in /home/sydney/HeliosOS/app/ai_client.py:242]
2025-08-10 01:20:08,277 ERROR: Request failed for model facebook/bart-large-cnn: 401 Client Error: Unauthorized for url: https://api-inference.huggingface.co/models/facebook/bart-large-cnn [in /home/sydney/HeliosOS/app/ai_client.py:65]
2025-08-10 01:20:08,278 ERROR: Summarization failed: RetryError[<Future at 0x7f465b194140 state=finished raised AIServiceError>] [in /home/sydney/HeliosOS/app/ai_client.py:108]
2025-08-10 01:20:08,278 WARNING: Database not available, skipping logging: The current Flask app is not registered with this 'SQLAlchemy' instance. Did you forget to call 'init_app', or did you create multiple 'SQLAlchemy' instances? [in /home/sydney/HeliosOS/app/ai_client.py:242]
2025-08-10 01:21:03,565 ERROR: Request failed for model facebook/bart-large-cnn: 401 Client Error: Unauthorized for url: https://api-inference.huggingface.co/models/facebook/bart-large-cnn [in /home/sydney/HeliosOS/app/ai_client.py:65]
2025-08-10 01:21:06,076 ERROR: Request failed for model facebook/bart-large-cnn: 401 Client Error: Unauthorized for url: https://api-inference.huggingface.co/models/facebook/bart-large-cnn [in /home/sydney/HeliosOS/app/ai_client.py:65]
2025-08-10 01:21:08,376 ERROR: Request failed for model facebook/bart-large-cnn: 401 Client Error: Unauthorized for url: https://api-inference.huggingface.co/models/facebook/bart-large-cnn [in /home/sydney/HeliosOS/app/ai_client.py:65]
2025-08-10 01:21:08,377 ERROR: Summarization failed: RetryError[<Future at 0x7f465b1bc740 state=finished raised AIServiceError>] [in /home/sydney/HeliosOS/app/ai_client.py:108]
2025-08-10 01:21:08,379 WARNING: Database not available, skipping logging: The current Flask app is not registered with this 'SQLAlchemy' instance. Did you forget to call 'init_app', or did you create multiple 'SQLAlchemy' instances? [in /home/sydney/HeliosOS/app/ai_client.py:242]
2025-08-10 02:01:41,976 INFO: Database tables created successfully [in /home/sydney/HeliosOS/app/__init__.py:97]
2025-08-10 02:02:00,041 WARNING: Database not available, skipping logging: The current Flask app is not registered with this 'SQLAlchemy' instance. Did you forget to call 'init_app', or did you create multiple 'SQLAlchemy' instances? [in /home/sydney/HeliosOS/app/ai_client.py:244]
2025-08-10 02:02:01,605 WARNING: Database not available, skipping logging: The current Flask app is not registered with this 'SQLAlchemy' instance. Did you forget to call 'init_app', or did you create multiple 'SQLAlchemy' instances? [in /home/sydney/HeliosOS/app/ai_client.py:244]
2025-08-10 02:02:31,475 WARNING: Database not available, skipping logging: The current Flask app is not registered with this 'SQLAlchemy' instance. Did you forget to call 'init_app', or did you create multiple 'SQLAlchemy' instances? [in /home/sydney/HeliosOS/app/ai_client.py:244]
2025-08-10 02:03:03,436 INFO: Database tables created successfully [in /home/sydney/HeliosOS/app/__init__.py:97]
2025-08-10 02:03:23,551 WARNING: Database not available, skipping logging: The current Flask app is not registered with this 'SQLAlchemy' instance. Did you forget to call 'init_app', or did you create multiple 'SQLAlchemy' instances? [in /home/sydney/HeliosOS/app/ai_client.py:244]
2025-08-10 02:03:30,673 WARNING: Database not available, skipping logging: The current Flask app is not registered with this 'SQLAlchemy' instance. Did you forget to call 'init_app', or did you create multiple 'SQLAlchemy' instances? [in /home/sydney/HeliosOS/app/ai_client.py:244]
2025-08-10 02:03:36,309 ERROR: Exception on /api/ai/chat [POST] [in /home/sydney/HeliosOS/venv/lib/python3.12/site-packages/flask/app.py:875]
Traceback (most recent call last):
  File "/home/sydney/HeliosOS/venv/lib/python3.12/site-packages/flask/app.py", line 1511, in wsgi_app
    response = self.full_dispatch_request()
               ^^^^^^^^^^^^^^^^^^^^^^^^^^^^
  File "/home/sydney/HeliosOS/venv/lib/python3.12/site-packages/flask/app.py", line 919, in full_dispatch_request
    rv = self.handle_user_exception(e)
         ^^^^^^^^^^^^^^^^^^^^^^^^^^^^^
  File "/home/sydney/HeliosOS/venv/lib/python3.12/site-packages/flask/app.py", line 917, in full_dispatch_request
    rv = self.dispatch_request()
         ^^^^^^^^^^^^^^^^^^^^^^^
  File "/home/sydney/HeliosOS/venv/lib/python3.12/site-packages/flask/app.py", line 902, in dispatch_request
    return self.ensure_sync(self.view_functions[rule.endpoint])(**view_args)  # type: ignore[no-any-return]
           ^^^^^^^^^^^^^^^^^^^^^^^^^^^^^^^^^^^^^^^^^^^^^^^^^^^^^^^^^^^^^^^^^
  File "/home/sydney/HeliosOS/venv/lib/python3.12/site-packages/flask_login/utils.py", line 285, in decorated_view
    return current_app.login_manager.unauthorized()
           ^^^^^^^^^^^^^^^^^^^^^^^^^^^^^^^^^^^^^^^^
  File "/home/sydney/HeliosOS/venv/lib/python3.12/site-packages/flask_login/login_manager.py", line 196, in unauthorized
    redirect_url = make_login_url(login_view, next_url=request.url)
                   ^^^^^^^^^^^^^^^^^^^^^^^^^^^^^^^^^^^^^^^^^^^^^^^^
  File "/home/sydney/HeliosOS/venv/lib/python3.12/site-packages/flask_login/utils.py", line 120, in login_url
    base = expand_login_view(login_view)
           ^^^^^^^^^^^^^^^^^^^^^^^^^^^^^
  File "/home/sydney/HeliosOS/venv/lib/python3.12/site-packages/flask_login/utils.py", line 97, in expand_login_view
    return url_for(login_view)
           ^^^^^^^^^^^^^^^^^^^
  File "/home/sydney/HeliosOS/venv/lib/python3.12/site-packages/flask/helpers.py", line 232, in url_for
    return current_app.url_for(
           ^^^^^^^^^^^^^^^^^^^^
  File "/home/sydney/HeliosOS/venv/lib/python3.12/site-packages/flask/app.py", line 1121, in url_for
    return self.handle_url_build_error(error, endpoint, values)
           ^^^^^^^^^^^^^^^^^^^^^^^^^^^^^^^^^^^^^^^^^^^^^^^^^^^^
  File "/home/sydney/HeliosOS/venv/lib/python3.12/site-packages/flask/app.py", line 1110, in url_for
    rv = url_adapter.build(  # type: ignore[union-attr]
         ^^^^^^^^^^^^^^^^^^^^^^^^^^^^^^^^^^^^^^^^^^^^^^
  File "/home/sydney/HeliosOS/venv/lib/python3.12/site-packages/werkzeug/routing/map.py", line 924, in build
    raise BuildError(endpoint, values, method, self)
werkzeug.routing.exceptions.BuildError: Could not build url for endpoint 'auth.login'. Did you mean 'main.index' instead?
2025-08-10 02:03:36,328 ERROR: Internal server error: 500 Internal Server Error: The server encountered an internal error and was unable to complete your request. Either the server is overloaded or there is an error in the application. [in /home/sydney/HeliosOS/app/__init__.py:127]
2025-08-10 02:03:53,049 WARNING: Database not available, skipping logging: The current Flask app is not registered with this 'SQLAlchemy' instance. Did you forget to call 'init_app', or did you create multiple 'SQLAlchemy' instances? [in /home/sydney/HeliosOS/app/ai_client.py:244]
2025-08-10 02:04:00,985 WARNING: Database not available, skipping logging: The current Flask app is not registered with this 'SQLAlchemy' instance. Did you forget to call 'init_app', or did you create multiple 'SQLAlchemy' instances? [in /home/sydney/HeliosOS/app/ai_client.py:244]
2025-08-10 02:04:02,750 WARNING: Database not available, skipping logging: The current Flask app is not registered with this 'SQLAlchemy' instance. Did you forget to call 'init_app', or did you create multiple 'SQLAlchemy' instances? [in /home/sydney/HeliosOS/app/ai_client.py:244]
2025-08-10 02:04:23,079 WARNING: Database not available, skipping logging: The current Flask app is not registered with this 'SQLAlchemy' instance. Did you forget to call 'init_app', or did you create multiple 'SQLAlchemy' instances? [in /home/sydney/HeliosOS/app/ai_client.py:244]
2025-08-10 02:04:30,923 WARNING: Database not available, skipping logging: The current Flask app is not registered with this 'SQLAlchemy' instance. Did you forget to call 'init_app', or did you create multiple 'SQLAlchemy' instances? [in /home/sydney/HeliosOS/app/ai_client.py:244]
2025-08-10 02:04:53,158 WARNING: Database not available, skipping logging: The current Flask app is not registered with this 'SQLAlchemy' instance. Did you forget to call 'init_app', or did you create multiple 'SQLAlchemy' instances? [in /home/sydney/HeliosOS/app/ai_client.py:244]
2025-08-10 02:05:02,227 WARNING: Database not available, skipping logging: The current Flask app is not registered with this 'SQLAlchemy' instance. Did you forget to call 'init_app', or did you create multiple 'SQLAlchemy' instances? [in /home/sydney/HeliosOS/app/ai_client.py:244]
2025-08-10 02:05:03,227 WARNING: Database not available, skipping logging: The current Flask app is not registered with this 'SQLAlchemy' instance. Did you forget to call 'init_app', or did you create multiple 'SQLAlchemy' instances? [in /home/sydney/HeliosOS/app/ai_client.py:244]
2025-08-10 02:05:23,307 WARNING: Database not available, skipping logging: The current Flask app is not registered with this 'SQLAlchemy' instance. Did you forget to call 'init_app', or did you create multiple 'SQLAlchemy' instances? [in /home/sydney/HeliosOS/app/ai_client.py:244]
2025-08-10 02:05:52,411 WARNING: Database not available, skipping logging: The current Flask app is not registered with this 'SQLAlchemy' instance. Did you forget to call 'init_app', or did you create multiple 'SQLAlchemy' instances? [in /home/sydney/HeliosOS/app/ai_client.py:244]
2025-08-10 02:06:02,186 WARNING: Database not available, skipping logging: The current Flask app is not registered with this 'SQLAlchemy' instance. Did you forget to call 'init_app', or did you create multiple 'SQLAlchemy' instances? [in /home/sydney/HeliosOS/app/ai_client.py:244]
2025-08-10 02:06:02,280 WARNING: Database not available, skipping logging: The current Flask app is not registered with this 'SQLAlchemy' instance. Did you forget to call 'init_app', or did you create multiple 'SQLAlchemy' instances? [in /home/sydney/HeliosOS/app/ai_client.py:244]
2025-08-10 02:06:22,582 WARNING: Database not available, skipping logging: The current Flask app is not registered with this 'SQLAlchemy' instance. Did you forget to call 'init_app', or did you create multiple 'SQLAlchemy' instances? [in /home/sydney/HeliosOS/app/ai_client.py:244]
2025-08-10 02:07:02,324 WARNING: Database not available, skipping logging: The current Flask app is not registered with this 'SQLAlchemy' instance. Did you forget to call 'init_app', or did you create multiple 'SQLAlchemy' instances? [in /home/sydney/HeliosOS/app/ai_client.py:244]
2025-08-10 02:07:02,418 WARNING: Database not available, skipping logging: The current Flask app is not registered with this 'SQLAlchemy' instance. Did you forget to call 'init_app', or did you create multiple 'SQLAlchemy' instances? [in /home/sydney/HeliosOS/app/ai_client.py:244]
2025-08-10 02:07:02,872 WARNING: Database not available, skipping logging: The current Flask app is not registered with this 'SQLAlchemy' instance. Did you forget to call 'init_app', or did you create multiple 'SQLAlchemy' instances? [in /home/sydney/HeliosOS/app/ai_client.py:244]
2025-08-10 02:08:02,565 WARNING: Database not available, skipping logging: The current Flask app is not registered with this 'SQLAlchemy' instance. Did you forget to call 'init_app', or did you create multiple 'SQLAlchemy' instances? [in /home/sydney/HeliosOS/app/ai_client.py:244]
2025-08-10 02:08:02,858 WARNING: Database not available, skipping logging: The current Flask app is not registered with this 'SQLAlchemy' instance. Did you forget to call 'init_app', or did you create multiple 'SQLAlchemy' instances? [in /home/sydney/HeliosOS/app/ai_client.py:244]
2025-08-10 02:08:03,618 WARNING: Database not available, skipping logging: The current Flask app is not registered with this 'SQLAlchemy' instance. Did you forget to call 'init_app', or did you create multiple 'SQLAlchemy' instances? [in /home/sydney/HeliosOS/app/ai_client.py:244]
2025-08-10 02:09:01,159 WARNING: Database not available, skipping logging: The current Flask app is not registered with this 'SQLAlchemy' instance. Did you forget to call 'init_app', or did you create multiple 'SQLAlchemy' instances? [in /home/sydney/HeliosOS/app/ai_client.py:244]
2025-08-10 02:09:01,239 WARNING: Database not available, skipping logging: The current Flask app is not registered with this 'SQLAlchemy' instance. Did you forget to call 'init_app', or did you create multiple 'SQLAlchemy' instances? [in /home/sydney/HeliosOS/app/ai_client.py:244]
2025-08-10 02:09:03,147 WARNING: Database not available, skipping logging: The current Flask app is not registered with this 'SQLAlchemy' instance. Did you forget to call 'init_app', or did you create multiple 'SQLAlchemy' instances? [in /home/sydney/HeliosOS/app/ai_client.py:244]
2025-08-10 02:10:02,107 WARNING: Database not available, skipping logging: The current Flask app is not registered with this 'SQLAlchemy' instance. Did you forget to call 'init_app', or did you create multiple 'SQLAlchemy' instances? [in /home/sydney/HeliosOS/app/ai_client.py:244]
2025-08-10 02:10:02,183 WARNING: Database not available, skipping logging: The current Flask app is not registered with this 'SQLAlchemy' instance. Did you forget to call 'init_app', or did you create multiple 'SQLAlchemy' instances? [in /home/sydney/HeliosOS/app/ai_client.py:244]
2025-08-10 02:10:02,529 WARNING: Database not available, skipping logging: The current Flask app is not registered with this 'SQLAlchemy' instance. Did you forget to call 'init_app', or did you create multiple 'SQLAlchemy' instances? [in /home/sydney/HeliosOS/app/ai_client.py:244]
2025-08-10 02:11:02,357 WARNING: Database not available, skipping logging: The current Flask app is not registered with this 'SQLAlchemy' instance. Did you forget to call 'init_app', or did you create multiple 'SQLAlchemy' instances? [in /home/sydney/HeliosOS/app/ai_client.py:244]
2025-08-10 02:11:02,443 WARNING: Database not available, skipping logging: The current Flask app is not registered with this 'SQLAlchemy' instance. Did you forget to call 'init_app', or did you create multiple 'SQLAlchemy' instances? [in /home/sydney/HeliosOS/app/ai_client.py:244]
2025-08-10 02:11:02,913 WARNING: Database not available, skipping logging: The current Flask app is not registered with this 'SQLAlchemy' instance. Did you forget to call 'init_app', or did you create multiple 'SQLAlchemy' instances? [in /home/sydney/HeliosOS/app/ai_client.py:244]
2025-08-10 02:12:02,282 WARNING: Database not available, skipping logging: The current Flask app is not registered with this 'SQLAlchemy' instance. Did you forget to call 'init_app', or did you create multiple 'SQLAlchemy' instances? [in /home/sydney/HeliosOS/app/ai_client.py:244]
2025-08-10 02:12:02,377 WARNING: Database not available, skipping logging: The current Flask app is not registered with this 'SQLAlchemy' instance. Did you forget to call 'init_app', or did you create multiple 'SQLAlchemy' instances? [in /home/sydney/HeliosOS/app/ai_client.py:244]
2025-08-10 02:12:02,758 WARNING: Database not available, skipping logging: The current Flask app is not registered with this 'SQLAlchemy' instance. Did you forget to call 'init_app', or did you create multiple 'SQLAlchemy' instances? [in /home/sydney/HeliosOS/app/ai_client.py:244]
2025-08-10 02:13:43,242 WARNING: Database not available, skipping logging: The current Flask app is not registered with this 'SQLAlchemy' instance. Did you forget to call 'init_app', or did you create multiple 'SQLAlchemy' instances? [in /home/sydney/HeliosOS/app/ai_client.py:244]
2025-08-10 02:13:43,922 WARNING: Database not available, skipping logging: The current Flask app is not registered with this 'SQLAlchemy' instance. Did you forget to call 'init_app', or did you create multiple 'SQLAlchemy' instances? [in /home/sydney/HeliosOS/app/ai_client.py:244]
2025-08-10 02:13:49,612 WARNING: Database not available, skipping logging: The current Flask app is not registered with this 'SQLAlchemy' instance. Did you forget to call 'init_app', or did you create multiple 'SQLAlchemy' instances? [in /home/sydney/HeliosOS/app/ai_client.py:244]
2025-08-10 02:14:02,338 WARNING: Database not available, skipping logging: The current Flask app is not registered with this 'SQLAlchemy' instance. Did you forget to call 'init_app', or did you create multiple 'SQLAlchemy' instances? [in /home/sydney/HeliosOS/app/ai_client.py:244]
2025-08-10 02:15:01,842 WARNING: Database not available, skipping logging: The current Flask app is not registered with this 'SQLAlchemy' instance. Did you forget to call 'init_app', or did you create multiple 'SQLAlchemy' instances? [in /home/sydney/HeliosOS/app/ai_client.py:244]
2025-08-10 02:15:22,298 WARNING: Database not available, skipping logging: The current Flask app is not registered with this 'SQLAlchemy' instance. Did you forget to call 'init_app', or did you create multiple 'SQLAlchemy' instances? [in /home/sydney/HeliosOS/app/ai_client.py:244]
2025-08-10 02:15:52,742 WARNING: Database not available, skipping logging: The current Flask app is not registered with this 'SQLAlchemy' instance. Did you forget to call 'init_app', or did you create multiple 'SQLAlchemy' instances? [in /home/sydney/HeliosOS/app/ai_client.py:244]
2025-08-10 02:16:08,745 INFO: Database tables created successfully [in /home/sydney/HeliosOS/app/__init__.py:97]
2025-08-10 02:16:20,635 WARNING: Database not available, skipping logging: The current Flask app is not registered with this 'SQLAlchemy' instance. Did you forget to call 'init_app', or did you create multiple 'SQLAlchemy' instances? [in /home/sydney/HeliosOS/app/ai_client.py:244]
2025-08-10 02:16:23,185 WARNING: Database not available, skipping logging: The current Flask app is not registered with this 'SQLAlchemy' instance. Did you forget to call 'init_app', or did you create multiple 'SQLAlchemy' instances? [in /home/sydney/HeliosOS/app/ai_client.py:244]
2025-08-10 02:16:51,883 WARNING: Database not available, skipping logging: The current Flask app is not registered with this 'SQLAlchemy' instance. Did you forget to call 'init_app', or did you create multiple 'SQLAlchemy' instances? [in /home/sydney/HeliosOS/app/ai_client.py:244]
2025-08-10 02:16:53,154 WARNING: Database not available, skipping logging: The current Flask app is not registered with this 'SQLAlchemy' instance. Did you forget to call 'init_app', or did you create multiple 'SQLAlchemy' instances? [in /home/sydney/HeliosOS/app/ai_client.py:244]
2025-08-10 02:17:21,874 WARNING: Database not available, skipping logging: The current Flask app is not registered with this 'SQLAlchemy' instance. Did you forget to call 'init_app', or did you create multiple 'SQLAlchemy' instances? [in /home/sydney/HeliosOS/app/ai_client.py:244]
2025-08-10 02:17:51,960 WARNING: Database not available, skipping logging: The current Flask app is not registered with this 'SQLAlchemy' instance. Did you forget to call 'init_app', or did you create multiple 'SQLAlchemy' instances? [in /home/sydney/HeliosOS/app/ai_client.py:244]
2025-08-10 02:18:03,110 WARNING: Database not available, skipping logging: The current Flask app is not registered with this 'SQLAlchemy' instance. Did you forget to call 'init_app', or did you create multiple 'SQLAlchemy' instances? [in /home/sydney/HeliosOS/app/ai_client.py:244]
2025-08-10 02:18:20,709 WARNING: Database not available, skipping logging: The current Flask app is not registered with this 'SQLAlchemy' instance. Did you forget to call 'init_app', or did you create multiple 'SQLAlchemy' instances? [in /home/sydney/HeliosOS/app/ai_client.py:244]
2025-08-10 02:18:50,682 WARNING: Database not available, skipping logging: The current Flask app is not registered with this 'SQLAlchemy' instance. Did you forget to call 'init_app', or did you create multiple 'SQLAlchemy' instances? [in /home/sydney/HeliosOS/app/ai_client.py:244]
2025-08-10 02:19:02,798 WARNING: Database not available, skipping logging: The current Flask app is not registered with this 'SQLAlchemy' instance. Did you forget to call 'init_app', or did you create multiple 'SQLAlchemy' instances? [in /home/sydney/HeliosOS/app/ai_client.py:244]
2025-08-10 02:19:22,455 WARNING: Database not available, skipping logging: The current Flask app is not registered with this 'SQLAlchemy' instance. Did you forget to call 'init_app', or did you create multiple 'SQLAlchemy' instances? [in /home/sydney/HeliosOS/app/ai_client.py:244]
2025-08-10 02:19:23,051 WARNING: Database not available, skipping logging: The current Flask app is not registered with this 'SQLAlchemy' instance. Did you forget to call 'init_app', or did you create multiple 'SQLAlchemy' instances? [in /home/sydney/HeliosOS/app/ai_client.py:244]
2025-08-10 02:19:23,680 WARNING: Database not available, skipping logging: The current Flask app is not registered with this 'SQLAlchemy' instance. Did you forget to call 'init_app', or did you create multiple 'SQLAlchemy' instances? [in /home/sydney/HeliosOS/app/ai_client.py:244]
2025-08-10 02:19:31,382 WARNING: Database not available, skipping logging: The current Flask app is not registered with this 'SQLAlchemy' instance. Did you forget to call 'init_app', or did you create multiple 'SQLAlchemy' instances? [in /home/sydney/HeliosOS/app/ai_client.py:244]
2025-08-10 02:19:36,861 WARNING: Database not available, skipping logging: The current Flask app is not registered with this 'SQLAlchemy' instance. Did you forget to call 'init_app', or did you create multiple 'SQLAlchemy' instances? [in /home/sydney/HeliosOS/app/ai_client.py:244]
2025-08-10 02:19:52,664 WARNING: Database not available, skipping logging: The current Flask app is not registered with this 'SQLAlchemy' instance. Did you forget to call 'init_app', or did you create multiple 'SQLAlchemy' instances? [in /home/sydney/HeliosOS/app/ai_client.py:244]
2025-08-10 02:20:01,130 WARNING: Database not available, skipping logging: The current Flask app is not registered with this 'SQLAlchemy' instance. Did you forget to call 'init_app', or did you create multiple 'SQLAlchemy' instances? [in /home/sydney/HeliosOS/app/ai_client.py:244]
2025-08-10 02:20:04,874 WARNING: Database not available, skipping logging: The current Flask app is not registered with this 'SQLAlchemy' instance. Did you forget to call 'init_app', or did you create multiple 'SQLAlchemy' instances? [in /home/sydney/HeliosOS/app/ai_client.py:244]
2025-08-10 02:20:22,732 WARNING: Database not available, skipping logging: The current Flask app is not registered with this 'SQLAlchemy' instance. Did you forget to call 'init_app', or did you create multiple 'SQLAlchemy' instances? [in /home/sydney/HeliosOS/app/ai_client.py:244]
2025-08-10 02:20:25,962 WARNING: Database not available, skipping logging: The current Flask app is not registered with this 'SQLAlchemy' instance. Did you forget to call 'init_app', or did you create multiple 'SQLAlchemy' instances? [in /home/sydney/HeliosOS/app/ai_client.py:244]
2025-08-10 02:20:36,102 WARNING: Database not available, skipping logging: The current Flask app is not registered with this 'SQLAlchemy' instance. Did you forget to call 'init_app', or did you create multiple 'SQLAlchemy' instances? [in /home/sydney/HeliosOS/app/ai_client.py:244]
2025-08-10 02:21:01,679 WARNING: Database not available, skipping logging: The current Flask app is not registered with this 'SQLAlchemy' instance. Did you forget to call 'init_app', or did you create multiple 'SQLAlchemy' instances? [in /home/sydney/HeliosOS/app/ai_client.py:244]
2025-08-10 02:21:04,471 WARNING: Database not available, skipping logging: The current Flask app is not registered with this 'SQLAlchemy' instance. Did you forget to call 'init_app', or did you create multiple 'SQLAlchemy' instances? [in /home/sydney/HeliosOS/app/ai_client.py:244]
2025-08-10 02:21:04,701 WARNING: Database not available, skipping logging: The current Flask app is not registered with this 'SQLAlchemy' instance. Did you forget to call 'init_app', or did you create multiple 'SQLAlchemy' instances? [in /home/sydney/HeliosOS/app/ai_client.py:244]
2025-08-10 02:21:04,994 WARNING: Database not available, skipping logging: The current Flask app is not registered with this 'SQLAlchemy' instance. Did you forget to call 'init_app', or did you create multiple 'SQLAlchemy' instances? [in /home/sydney/HeliosOS/app/ai_client.py:244]
2025-08-10 02:21:34,345 WARNING: Database not available, skipping logging: The current Flask app is not registered with this 'SQLAlchemy' instance. Did you forget to call 'init_app', or did you create multiple 'SQLAlchemy' instances? [in /home/sydney/HeliosOS/app/ai_client.py:244]
2025-08-10 02:22:01,860 WARNING: Database not available, skipping logging: The current Flask app is not registered with this 'SQLAlchemy' instance. Did you forget to call 'init_app', or did you create multiple 'SQLAlchemy' instances? [in /home/sydney/HeliosOS/app/ai_client.py:244]
2025-08-10 02:22:03,300 WARNING: Database not available, skipping logging: The current Flask app is not registered with this 'SQLAlchemy' instance. Did you forget to call 'init_app', or did you create multiple 'SQLAlchemy' instances? [in /home/sydney/HeliosOS/app/ai_client.py:244]
2025-08-10 02:22:05,377 WARNING: Database not available, skipping logging: The current Flask app is not registered with this 'SQLAlchemy' instance. Did you forget to call 'init_app', or did you create multiple 'SQLAlchemy' instances? [in /home/sydney/HeliosOS/app/ai_client.py:244]
2025-08-10 02:22:07,508 WARNING: Database not available, skipping logging: The current Flask app is not registered with this 'SQLAlchemy' instance. Did you forget to call 'init_app', or did you create multiple 'SQLAlchemy' instances? [in /home/sydney/HeliosOS/app/ai_client.py:244]
2025-08-10 02:22:34,833 WARNING: Database not available, skipping logging: The current Flask app is not registered with this 'SQLAlchemy' instance. Did you forget to call 'init_app', or did you create multiple 'SQLAlchemy' instances? [in /home/sydney/HeliosOS/app/ai_client.py:244]
2025-08-10 02:23:02,297 WARNING: Database not available, skipping logging: The current Flask app is not registered with this 'SQLAlchemy' instance. Did you forget to call 'init_app', or did you create multiple 'SQLAlchemy' instances? [in /home/sydney/HeliosOS/app/ai_client.py:244]
2025-08-10 02:23:11,066 WARNING: Database not available, skipping logging: The current Flask app is not registered with this 'SQLAlchemy' instance. Did you forget to call 'init_app', or did you create multiple 'SQLAlchemy' instances? [in /home/sydney/HeliosOS/app/ai_client.py:244]
2025-08-10 02:23:12,366 WARNING: Database not available, skipping logging: The current Flask app is not registered with this 'SQLAlchemy' instance. Did you forget to call 'init_app', or did you create multiple 'SQLAlchemy' instances? [in /home/sydney/HeliosOS/app/ai_client.py:244]
2025-08-10 02:24:02,409 WARNING: Database not available, skipping logging: The current Flask app is not registered with this 'SQLAlchemy' instance. Did you forget to call 'init_app', or did you create multiple 'SQLAlchemy' instances? [in /home/sydney/HeliosOS/app/ai_client.py:244]
2025-08-10 02:24:02,554 WARNING: Database not available, skipping logging: The current Flask app is not registered with this 'SQLAlchemy' instance. Did you forget to call 'init_app', or did you create multiple 'SQLAlchemy' instances? [in /home/sydney/HeliosOS/app/ai_client.py:244]
2025-08-10 02:24:02,897 WARNING: Database not available, skipping logging: The current Flask app is not registered with this 'SQLAlchemy' instance. Did you forget to call 'init_app', or did you create multiple 'SQLAlchemy' instances? [in /home/sydney/HeliosOS/app/ai_client.py:244]
2025-08-10 02:25:01,698 WARNING: Database not available, skipping logging: The current Flask app is not registered with this 'SQLAlchemy' instance. Did you forget to call 'init_app', or did you create multiple 'SQLAlchemy' instances? [in /home/sydney/HeliosOS/app/ai_client.py:244]
2025-08-10 02:25:01,758 WARNING: Database not available, skipping logging: The current Flask app is not registered with this 'SQLAlchemy' instance. Did you forget to call 'init_app', or did you create multiple 'SQLAlchemy' instances? [in /home/sydney/HeliosOS/app/ai_client.py:244]
2025-08-10 02:25:02,763 WARNING: Database not available, skipping logging: The current Flask app is not registered with this 'SQLAlchemy' instance. Did you forget to call 'init_app', or did you create multiple 'SQLAlchemy' instances? [in /home/sydney/HeliosOS/app/ai_client.py:244]
2025-08-10 02:26:02,453 WARNING: Database not available, skipping logging: The current Flask app is not registered with this 'SQLAlchemy' instance. Did you forget to call 'init_app', or did you create multiple 'SQLAlchemy' instances? [in /home/sydney/HeliosOS/app/ai_client.py:244]
2025-08-10 02:26:05,156 WARNING: Database not available, skipping logging: The current Flask app is not registered with this 'SQLAlchemy' instance. Did you forget to call 'init_app', or did you create multiple 'SQLAlchemy' instances? [in /home/sydney/HeliosOS/app/ai_client.py:244]
2025-08-10 02:26:05,258 WARNING: Database not available, skipping logging: The current Flask app is not registered with this 'SQLAlchemy' instance. Did you forget to call 'init_app', or did you create multiple 'SQLAlchemy' instances? [in /home/sydney/HeliosOS/app/ai_client.py:244]
2025-08-10 02:27:02,023 INFO: Database tables created successfully [in /home/sydney/HeliosOS/app/__init__.py:97]
2025-08-10 02:27:04,654 WARNING: Database not available, skipping logging: The current Flask app is not registered with this 'SQLAlchemy' instance. Did you forget to call 'init_app', or did you create multiple 'SQLAlchemy' instances? [in /home/sydney/HeliosOS/app/ai_client.py:244]
2025-08-10 02:27:04,744 WARNING: Database not available, skipping logging: The current Flask app is not registered with this 'SQLAlchemy' instance. Did you forget to call 'init_app', or did you create multiple 'SQLAlchemy' instances? [in /home/sydney/HeliosOS/app/ai_client.py:244]
2025-08-10 02:27:05,173 WARNING: Database not available, skipping logging: The current Flask app is not registered with this 'SQLAlchemy' instance. Did you forget to call 'init_app', or did you create multiple 'SQLAlchemy' instances? [in /home/sydney/HeliosOS/app/ai_client.py:244]
2025-08-10 02:27:10,220 WARNING: Database not available, skipping logging: The current Flask app is not registered with this 'SQLAlchemy' instance. Did you forget to call 'init_app', or did you create multiple 'SQLAlchemy' instances? [in /home/sydney/HeliosOS/app/ai_client.py:244]
2025-08-10 02:27:39,763 WARNING: Database not available, skipping logging: The current Flask app is not registered with this 'SQLAlchemy' instance. Did you forget to call 'init_app', or did you create multiple 'SQLAlchemy' instances? [in /home/sydney/HeliosOS/app/ai_client.py:244]
2025-08-10 02:28:04,551 WARNING: Database not available, skipping logging: The current Flask app is not registered with this 'SQLAlchemy' instance. Did you forget to call 'init_app', or did you create multiple 'SQLAlchemy' instances? [in /home/sydney/HeliosOS/app/ai_client.py:244]
2025-08-10 02:28:04,823 WARNING: Database not available, skipping logging: The current Flask app is not registered with this 'SQLAlchemy' instance. Did you forget to call 'init_app', or did you create multiple 'SQLAlchemy' instances? [in /home/sydney/HeliosOS/app/ai_client.py:244]
2025-08-10 02:28:05,361 WARNING: Database not available, skipping logging: The current Flask app is not registered with this 'SQLAlchemy' instance. Did you forget to call 'init_app', or did you create multiple 'SQLAlchemy' instances? [in /home/sydney/HeliosOS/app/ai_client.py:244]
2025-08-10 02:28:09,433 WARNING: Database not available, skipping logging: The current Flask app is not registered with this 'SQLAlchemy' instance. Did you forget to call 'init_app', or did you create multiple 'SQLAlchemy' instances? [in /home/sydney/HeliosOS/app/ai_client.py:244]
2025-08-10 02:28:39,616 WARNING: Database not available, skipping logging: The current Flask app is not registered with this 'SQLAlchemy' instance. Did you forget to call 'init_app', or did you create multiple 'SQLAlchemy' instances? [in /home/sydney/HeliosOS/app/ai_client.py:244]
2025-08-10 04:15:14,460 INFO: Database tables created successfully [in C:\Users\HP\Downloads\Helios\HeliosOS\app\__init__.py:97]
2025-08-13 14:52:18,659 INFO: Database tables created successfully [in /home/sydney/HeliosOS/app/__init__.py:97]
2025-08-13 14:53:36,243 ERROR: Request failed for model facebook/bart-large-cnn: 401 Client Error: Unauthorized for url: https://api-inference.huggingface.co/models/facebook/bart-large-cnn [in /home/sydney/HeliosOS/app/ai_client.py:65]
2025-08-13 14:53:38,459 ERROR: Request failed for model facebook/bart-large-cnn: 401 Client Error: Unauthorized for url: https://api-inference.huggingface.co/models/facebook/bart-large-cnn [in /home/sydney/HeliosOS/app/ai_client.py:65]
2025-08-13 14:53:40,674 ERROR: Request failed for model facebook/bart-large-cnn: 401 Client Error: Unauthorized for url: https://api-inference.huggingface.co/models/facebook/bart-large-cnn [in /home/sydney/HeliosOS/app/ai_client.py:65]
2025-08-13 14:53:40,674 ERROR: Summarization failed: RetryError[<Future at 0x7f55a7e171d0 state=finished raised AIServiceError>] [in /home/sydney/HeliosOS/app/ai_client.py:113]
2025-08-13 14:53:40,718 WARNING: Failed to log AI interaction: (psycopg2.errors.UndefinedTable) relation "ai_interactions" does not exist
LINE 1: INSERT INTO ai_interactions (user_id, interaction_type, inpu...
                    ^

[SQL: INSERT INTO ai_interactions (user_id, interaction_type, input_text, output_text, model_used, response_time, tokens_used, success, error_message, created_at) VALUES (%(user_id)s, %(interaction_type)s, %(input_text)s, %(output_text)s, %(model_used)s, %(response_time)s, %(tokens_used)s, %(success)s, %(error_message)s, %(created_at)s) RETURNING ai_interactions.id]
[parameters: {'user_id': None, 'interaction_type': 'summarize', 'input_text': 'This is a short test for health check.', 'output_text': None, 'model_used': 'facebook/bart-large-cnn', 'response_time': 4.750513315200806, 'tokens_used': None, 'success': False, 'error_message': 'RetryError[<Future at 0x7f55a7e171d0 state=finished raised AIServiceError>]', 'created_at': datetime.datetime(2025, 8, 13, 11, 53, 40, 715225)}]
(Background on this error at: https://sqlalche.me/e/20/f405) [in /home/sydney/HeliosOS/app/ai_client.py:280]
2025-08-13 14:54:06,644 ERROR: Request failed for model facebook/bart-large-cnn: 401 Client Error: Unauthorized for url: https://api-inference.huggingface.co/models/facebook/bart-large-cnn [in /home/sydney/HeliosOS/app/ai_client.py:65]
2025-08-13 14:54:08,861 ERROR: Request failed for model facebook/bart-large-cnn: 401 Client Error: Unauthorized for url: https://api-inference.huggingface.co/models/facebook/bart-large-cnn [in /home/sydney/HeliosOS/app/ai_client.py:65]
2025-08-13 14:54:11,084 ERROR: Request failed for model facebook/bart-large-cnn: 401 Client Error: Unauthorized for url: https://api-inference.huggingface.co/models/facebook/bart-large-cnn [in /home/sydney/HeliosOS/app/ai_client.py:65]
2025-08-13 14:54:11,085 ERROR: Summarization failed: RetryError[<Future at 0x7f55a6d54ef0 state=finished raised AIServiceError>] [in /home/sydney/HeliosOS/app/ai_client.py:113]
2025-08-13 14:54:11,090 WARNING: Failed to log AI interaction: (psycopg2.errors.UndefinedTable) relation "ai_interactions" does not exist
LINE 1: INSERT INTO ai_interactions (user_id, interaction_type, inpu...
                    ^

[SQL: INSERT INTO ai_interactions (user_id, interaction_type, input_text, output_text, model_used, response_time, tokens_used, success, error_message, created_at) VALUES (%(user_id)s, %(interaction_type)s, %(input_text)s, %(output_text)s, %(model_used)s, %(response_time)s, %(tokens_used)s, %(success)s, %(error_message)s, %(created_at)s) RETURNING ai_interactions.id]
[parameters: {'user_id': None, 'interaction_type': 'summarize', 'input_text': 'This is a short test for health check.', 'output_text': None, 'model_used': 'facebook/bart-large-cnn', 'response_time': 4.715510129928589, 'tokens_used': None, 'success': False, 'error_message': 'RetryError[<Future at 0x7f55a6d54ef0 state=finished raised AIServiceError>]', 'created_at': datetime.datetime(2025, 8, 13, 11, 54, 11, 88994)}]
(Background on this error at: https://sqlalche.me/e/20/f405) [in /home/sydney/HeliosOS/app/ai_client.py:280]
2025-08-13 14:54:12,613 ERROR: Request failed for model facebook/bart-large-cnn: 401 Client Error: Unauthorized for url: https://api-inference.huggingface.co/models/facebook/bart-large-cnn [in /home/sydney/HeliosOS/app/ai_client.py:65]
2025-08-13 14:54:14,833 ERROR: Request failed for model facebook/bart-large-cnn: 401 Client Error: Unauthorized for url: https://api-inference.huggingface.co/models/facebook/bart-large-cnn [in /home/sydney/HeliosOS/app/ai_client.py:65]
2025-08-13 14:54:17,051 ERROR: Request failed for model facebook/bart-large-cnn: 401 Client Error: Unauthorized for url: https://api-inference.huggingface.co/models/facebook/bart-large-cnn [in /home/sydney/HeliosOS/app/ai_client.py:65]
2025-08-13 14:54:17,051 ERROR: Summarization failed: RetryError[<Future at 0x7f55a6515be0 state=finished raised AIServiceError>] [in /home/sydney/HeliosOS/app/ai_client.py:113]
2025-08-13 14:54:17,057 WARNING: Failed to log AI interaction: (psycopg2.errors.UndefinedTable) relation "ai_interactions" does not exist
LINE 1: INSERT INTO ai_interactions (user_id, interaction_type, inpu...
                    ^

[SQL: INSERT INTO ai_interactions (user_id, interaction_type, input_text, output_text, model_used, response_time, tokens_used, success, error_message, created_at) VALUES (%(user_id)s, %(interaction_type)s, %(input_text)s, %(output_text)s, %(model_used)s, %(response_time)s, %(tokens_used)s, %(success)s, %(error_message)s, %(created_at)s) RETURNING ai_interactions.id]
[parameters: {'user_id': None, 'interaction_type': 'summarize', 'input_text': 'This is a short test for health check.', 'output_text': None, 'model_used': 'facebook/bart-large-cnn', 'response_time': 4.763618230819702, 'tokens_used': None, 'success': False, 'error_message': 'RetryError[<Future at 0x7f55a6515be0 state=finished raised AIServiceError>]', 'created_at': datetime.datetime(2025, 8, 13, 11, 54, 17, 55815)}]
(Background on this error at: https://sqlalche.me/e/20/f405) [in /home/sydney/HeliosOS/app/ai_client.py:280]
2025-08-13 14:54:21,256 INFO: Database tables created successfully [in /home/sydney/HeliosOS/app/__init__.py:97]
2025-08-13 14:54:25,657 ERROR: Request failed for model facebook/bart-large-cnn: 401 Client Error: Unauthorized for url: https://api-inference.huggingface.co/models/facebook/bart-large-cnn [in /home/sydney/HeliosOS/app/ai_client.py:65]
2025-08-13 14:54:27,881 ERROR: Request failed for model facebook/bart-large-cnn: 401 Client Error: Unauthorized for url: https://api-inference.huggingface.co/models/facebook/bart-large-cnn [in /home/sydney/HeliosOS/app/ai_client.py:65]
2025-08-13 14:54:30,101 ERROR: Request failed for model facebook/bart-large-cnn: 401 Client Error: Unauthorized for url: https://api-inference.huggingface.co/models/facebook/bart-large-cnn [in /home/sydney/HeliosOS/app/ai_client.py:65]
2025-08-13 14:54:30,102 ERROR: Summarization failed: RetryError[<Future at 0x7fc4f171cfe0 state=finished raised AIServiceError>] [in /home/sydney/HeliosOS/app/ai_client.py:113]
2025-08-13 14:54:30,141 WARNING: Failed to log AI interaction: (psycopg2.errors.UndefinedTable) relation "ai_interactions" does not exist
LINE 1: INSERT INTO ai_interactions (user_id, interaction_type, inpu...
                    ^

[SQL: INSERT INTO ai_interactions (user_id, interaction_type, input_text, output_text, model_used, response_time, tokens_used, success, error_message, created_at) VALUES (%(user_id)s, %(interaction_type)s, %(input_text)s, %(output_text)s, %(model_used)s, %(response_time)s, %(tokens_used)s, %(success)s, %(error_message)s, %(created_at)s) RETURNING ai_interactions.id]
[parameters: {'user_id': None, 'interaction_type': 'summarize', 'input_text': 'This is a short test for health check.', 'output_text': None, 'model_used': 'facebook/bart-large-cnn', 'response_time': 4.799939393997192, 'tokens_used': None, 'success': False, 'error_message': 'RetryError[<Future at 0x7fc4f171cfe0 state=finished raised AIServiceError>]', 'created_at': datetime.datetime(2025, 8, 13, 11, 54, 30, 138821)}]
(Background on this error at: https://sqlalche.me/e/20/f405) [in /home/sydney/HeliosOS/app/ai_client.py:280]
2025-08-13 14:54:30,443 ERROR: Request failed for model facebook/bart-large-cnn: 401 Client Error: Unauthorized for url: https://api-inference.huggingface.co/models/facebook/bart-large-cnn [in /home/sydney/HeliosOS/app/ai_client.py:65]
2025-08-13 14:54:35,592 ERROR: Request failed for model facebook/bart-large-cnn: 401 Client Error: Unauthorized for url: https://api-inference.huggingface.co/models/facebook/bart-large-cnn [in /home/sydney/HeliosOS/app/ai_client.py:65]
2025-08-13 14:54:37,829 ERROR: Request failed for model facebook/bart-large-cnn: 401 Client Error: Unauthorized for url: https://api-inference.huggingface.co/models/facebook/bart-large-cnn [in /home/sydney/HeliosOS/app/ai_client.py:65]
2025-08-13 14:54:37,829 ERROR: Summarization failed: RetryError[<Future at 0x7fc4f0b83fb0 state=finished raised AIServiceError>] [in /home/sydney/HeliosOS/app/ai_client.py:113]
2025-08-13 14:54:37,836 WARNING: Failed to log AI interaction: (psycopg2.errors.UndefinedTable) relation "ai_interactions" does not exist
LINE 1: INSERT INTO ai_interactions (user_id, interaction_type, inpu...
                    ^

[SQL: INSERT INTO ai_interactions (user_id, interaction_type, input_text, output_text, model_used, response_time, tokens_used, success, error_message, created_at) VALUES (%(user_id)s, %(interaction_type)s, %(input_text)s, %(output_text)s, %(model_used)s, %(response_time)s, %(tokens_used)s, %(success)s, %(error_message)s, %(created_at)s) RETURNING ai_interactions.id]
[parameters: {'user_id': None, 'interaction_type': 'summarize', 'input_text': 'This is a short test for health check.', 'output_text': None, 'model_used': 'facebook/bart-large-cnn', 'response_time': 7.669704437255859, 'tokens_used': None, 'success': False, 'error_message': 'RetryError[<Future at 0x7fc4f0b83fb0 state=finished raised AIServiceError>]', 'created_at': datetime.datetime(2025, 8, 13, 11, 54, 37, 834198)}]
(Background on this error at: https://sqlalche.me/e/20/f405) [in /home/sydney/HeliosOS/app/ai_client.py:280]
2025-08-13 14:54:56,032 ERROR: Request failed for model facebook/bart-large-cnn: 401 Client Error: Unauthorized for url: https://api-inference.huggingface.co/models/facebook/bart-large-cnn [in /home/sydney/HeliosOS/app/ai_client.py:65]
2025-08-13 14:54:57,635 ERROR: Exception on /api/exec [POST] [in /home/sydney/HeliosOS/venv/lib/python3.12/site-packages/flask/app.py:875]
Traceback (most recent call last):
  File "/home/sydney/HeliosOS/venv/lib/python3.12/site-packages/flask/app.py", line 1511, in wsgi_app
    response = self.full_dispatch_request()
               ^^^^^^^^^^^^^^^^^^^^^^^^^^^^
  File "/home/sydney/HeliosOS/venv/lib/python3.12/site-packages/flask/app.py", line 919, in full_dispatch_request
    rv = self.handle_user_exception(e)
         ^^^^^^^^^^^^^^^^^^^^^^^^^^^^^
  File "/home/sydney/HeliosOS/venv/lib/python3.12/site-packages/flask/app.py", line 917, in full_dispatch_request
    rv = self.dispatch_request()
         ^^^^^^^^^^^^^^^^^^^^^^^
  File "/home/sydney/HeliosOS/venv/lib/python3.12/site-packages/flask/app.py", line 902, in dispatch_request
    return self.ensure_sync(self.view_functions[rule.endpoint])(**view_args)  # type: ignore[no-any-return]
           ^^^^^^^^^^^^^^^^^^^^^^^^^^^^^^^^^^^^^^^^^^^^^^^^^^^^^^^^^^^^^^^^^
  File "/home/sydney/HeliosOS/venv/lib/python3.12/site-packages/flask_login/utils.py", line 285, in decorated_view
    return current_app.login_manager.unauthorized()
           ^^^^^^^^^^^^^^^^^^^^^^^^^^^^^^^^^^^^^^^^
  File "/home/sydney/HeliosOS/venv/lib/python3.12/site-packages/flask_login/login_manager.py", line 196, in unauthorized
    redirect_url = make_login_url(login_view, next_url=request.url)
                   ^^^^^^^^^^^^^^^^^^^^^^^^^^^^^^^^^^^^^^^^^^^^^^^^
  File "/home/sydney/HeliosOS/venv/lib/python3.12/site-packages/flask_login/utils.py", line 120, in login_url
    base = expand_login_view(login_view)
           ^^^^^^^^^^^^^^^^^^^^^^^^^^^^^
  File "/home/sydney/HeliosOS/venv/lib/python3.12/site-packages/flask_login/utils.py", line 97, in expand_login_view
    return url_for(login_view)
           ^^^^^^^^^^^^^^^^^^^
  File "/home/sydney/HeliosOS/venv/lib/python3.12/site-packages/flask/helpers.py", line 232, in url_for
    return current_app.url_for(
           ^^^^^^^^^^^^^^^^^^^^
  File "/home/sydney/HeliosOS/venv/lib/python3.12/site-packages/flask/app.py", line 1121, in url_for
    return self.handle_url_build_error(error, endpoint, values)
           ^^^^^^^^^^^^^^^^^^^^^^^^^^^^^^^^^^^^^^^^^^^^^^^^^^^^
  File "/home/sydney/HeliosOS/venv/lib/python3.12/site-packages/flask/app.py", line 1110, in url_for
    rv = url_adapter.build(  # type: ignore[union-attr]
         ^^^^^^^^^^^^^^^^^^^^^^^^^^^^^^^^^^^^^^^^^^^^^^
  File "/home/sydney/HeliosOS/venv/lib/python3.12/site-packages/werkzeug/routing/map.py", line 924, in build
    raise BuildError(endpoint, values, method, self)
werkzeug.routing.exceptions.BuildError: Could not build url for endpoint 'auth.login'. Did you mean 'main.index' instead?
2025-08-13 14:54:57,639 ERROR: Internal server error: 500 Internal Server Error: The server encountered an internal error and was unable to complete your request. Either the server is overloaded or there is an error in the application. [in /home/sydney/HeliosOS/app/__init__.py:127]
2025-08-13 14:54:58,249 ERROR: Request failed for model facebook/bart-large-cnn: 401 Client Error: Unauthorized for url: https://api-inference.huggingface.co/models/facebook/bart-large-cnn [in /home/sydney/HeliosOS/app/ai_client.py:65]
2025-08-13 14:55:00,466 ERROR: Request failed for model facebook/bart-large-cnn: 401 Client Error: Unauthorized for url: https://api-inference.huggingface.co/models/facebook/bart-large-cnn [in /home/sydney/HeliosOS/app/ai_client.py:65]
2025-08-13 14:55:00,466 ERROR: Summarization failed: RetryError[<Future at 0x7fc4f0b5efc0 state=finished raised AIServiceError>] [in /home/sydney/HeliosOS/app/ai_client.py:113]
2025-08-13 14:55:00,475 WARNING: Failed to log AI interaction: (psycopg2.errors.UndefinedTable) relation "ai_interactions" does not exist
LINE 1: INSERT INTO ai_interactions (user_id, interaction_type, inpu...
                    ^

[SQL: INSERT INTO ai_interactions (user_id, interaction_type, input_text, output_text, model_used, response_time, tokens_used, success, error_message, created_at) VALUES (%(user_id)s, %(interaction_type)s, %(input_text)s, %(output_text)s, %(model_used)s, %(response_time)s, %(tokens_used)s, %(success)s, %(error_message)s, %(created_at)s) RETURNING ai_interactions.id]
[parameters: {'user_id': None, 'interaction_type': 'summarize', 'input_text': 'This is a short test for health check.', 'output_text': None, 'model_used': 'facebook/bart-large-cnn', 'response_time': 4.7342164516448975, 'tokens_used': None, 'success': False, 'error_message': 'RetryError[<Future at 0x7fc4f0b5efc0 state=finished raised AIServiceError>]', 'created_at': datetime.datetime(2025, 8, 13, 11, 55, 0, 473567)}]
(Background on this error at: https://sqlalche.me/e/20/f405) [in /home/sydney/HeliosOS/app/ai_client.py:280]
2025-08-13 15:41:12,689 INFO: Database tables created successfully [in /home/sydney/HeliosOS/app/__init__.py:97]
2025-08-13 15:41:20,025 ERROR: Request failed for model facebook/bart-large-cnn: 401 Client Error: Unauthorized for url: https://api-inference.huggingface.co/models/facebook/bart-large-cnn [in /home/sydney/HeliosOS/app/ai_client.py:65]
2025-08-13 15:41:22,247 ERROR: Request failed for model facebook/bart-large-cnn: 401 Client Error: Unauthorized for url: https://api-inference.huggingface.co/models/facebook/bart-large-cnn [in /home/sydney/HeliosOS/app/ai_client.py:65]
2025-08-13 15:41:24,502 ERROR: Request failed for model facebook/bart-large-cnn: 401 Client Error: Unauthorized for url: https://api-inference.huggingface.co/models/facebook/bart-large-cnn [in /home/sydney/HeliosOS/app/ai_client.py:65]
2025-08-13 15:41:24,503 ERROR: Summarization failed: RetryError[<Future at 0x7efcbb704320 state=finished raised AIServiceError>] [in /home/sydney/HeliosOS/app/ai_client.py:113]
2025-08-13 15:41:24,656 WARNING: Failed to log AI interaction: (psycopg2.errors.UndefinedTable) relation "ai_interactions" does not exist
LINE 1: INSERT INTO ai_interactions (user_id, interaction_type, inpu...
                    ^

[SQL: INSERT INTO ai_interactions (user_id, interaction_type, input_text, output_text, model_used, response_time, tokens_used, success, error_message, created_at) VALUES (%(user_id)s, %(interaction_type)s, %(input_text)s, %(output_text)s, %(model_used)s, %(response_time)s, %(tokens_used)s, %(success)s, %(error_message)s, %(created_at)s) RETURNING ai_interactions.id]
[parameters: {'user_id': None, 'interaction_type': 'summarize', 'input_text': 'This is a short test for health check.', 'output_text': None, 'model_used': 'facebook/bart-large-cnn', 'response_time': 4.896299123764038, 'tokens_used': None, 'success': False, 'error_message': 'RetryError[<Future at 0x7efcbb704320 state=finished raised AIServiceError>]', 'created_at': datetime.datetime(2025, 8, 13, 12, 41, 24, 624861)}]
(Background on this error at: https://sqlalche.me/e/20/f405) [in /home/sydney/HeliosOS/app/ai_client.py:280]
2025-08-13 16:03:01,020 INFO: Database tables created successfully [in /home/sydney/HeliosOS/app/__init__.py:97]
2025-08-19 07:50:45,381 INFO: OpenAI client initialized successfully [in /home/ubuntu/HeliosOS/app/enhanced_ai_client.py:49]
2025-08-19 07:50:45,398 ERROR: Failed to create database tables: (psycopg2.OperationalError) connection to server at "localhost" (::1), port 5432 failed: Connection refused
	Is the server running on that host and accepting TCP/IP connections?
connection to server at "localhost" (127.0.0.1), port 5432 failed: Connection refused
	Is the server running on that host and accepting TCP/IP connections?

(Background on this error at: https://sqlalche.me/e/20/e3q8) [in /home/ubuntu/HeliosOS/app/__init__.py:103]
2025-08-19 07:50:45,931 ERROR: OpenAI processing failed: Error code: 400 - {'error': 'Unsupported model. Only the following models are allowed: gpt-4.1-mini, gpt-4.1-nano, gemini-2.5-flash'} [in /home/ubuntu/HeliosOS/app/enhanced_ai_client.py:147]
2025-08-19 07:50:45,945 ERROR: Failed to create database tables: (psycopg2.OperationalError) connection to server at "localhost" (::1), port 5432 failed: Connection refused
	Is the server running on that host and accepting TCP/IP connections?
connection to server at "localhost" (127.0.0.1), port 5432 failed: Connection refused
	Is the server running on that host and accepting TCP/IP connections?

(Background on this error at: https://sqlalche.me/e/20/e3q8) [in /home/ubuntu/HeliosOS/app/__init__.py:103]
2025-08-19 07:50:45,945 ERROR: Failed to create database tables: (psycopg2.OperationalError) connection to server at "localhost" (::1), port 5432 failed: Connection refused
	Is the server running on that host and accepting TCP/IP connections?
connection to server at "localhost" (127.0.0.1), port 5432 failed: Connection refused
	Is the server running on that host and accepting TCP/IP connections?

(Background on this error at: https://sqlalche.me/e/20/e3q8) [in /home/ubuntu/HeliosOS/app/__init__.py:103]
2025-08-19 07:51:17,236 INFO: OpenAI client initialized successfully [in /home/ubuntu/HeliosOS/app/enhanced_ai_client.py:49]
2025-08-19 07:51:17,257 ERROR: Failed to create database tables: (psycopg2.OperationalError) connection to server at "localhost" (::1), port 5432 failed: Connection refused
	Is the server running on that host and accepting TCP/IP connections?
connection to server at "localhost" (127.0.0.1), port 5432 failed: Connection refused
	Is the server running on that host and accepting TCP/IP connections?

(Background on this error at: https://sqlalche.me/e/20/e3q8) [in /home/ubuntu/HeliosOS/app/__init__.py:103]
2025-08-19 07:51:17,619 ERROR: OpenAI processing failed: Error code: 400 - {'error': 'Unsupported model. Only the following models are allowed: gemini-2.5-flash, gpt-4.1-mini, gpt-4.1-nano'} [in /home/ubuntu/HeliosOS/app/enhanced_ai_client.py:147]
2025-08-19 07:51:17,667 ERROR: Failed to create database tables: (psycopg2.OperationalError) connection to server at "localhost" (::1), port 5432 failed: Connection refused
	Is the server running on that host and accepting TCP/IP connections?
connection to server at "localhost" (127.0.0.1), port 5432 failed: Connection refused
	Is the server running on that host and accepting TCP/IP connections?

(Background on this error at: https://sqlalche.me/e/20/e3q8) [in /home/ubuntu/HeliosOS/app/__init__.py:103]
2025-08-19 07:51:17,667 ERROR: Failed to create database tables: (psycopg2.OperationalError) connection to server at "localhost" (::1), port 5432 failed: Connection refused
	Is the server running on that host and accepting TCP/IP connections?
connection to server at "localhost" (127.0.0.1), port 5432 failed: Connection refused
	Is the server running on that host and accepting TCP/IP connections?

(Background on this error at: https://sqlalche.me/e/20/e3q8) [in /home/ubuntu/HeliosOS/app/__init__.py:103]
2025-08-19 15:05:40,164 INFO: OpenAI client initialized successfully [in /home/sydney/HeliosOS/app/enhanced_ai_client.py:49]
2025-08-19 15:05:40,385 INFO: Database tables created successfully [in /home/sydney/HeliosOS/app/__init__.py:101]
2025-08-19 18:19:12,310 INFO: OpenAI client initialized successfully [in /home/sydney/HeliosOS/app/enhanced_ai_client.py:49]
2025-08-19 18:19:12,482 ERROR: Failed to create database tables: (psycopg2.OperationalError) connection to server at "localhost" (127.0.0.1), port 5432 failed: FATAL:  password authentication failed for user "sydney"

(Background on this error at: https://sqlalche.me/e/20/e3q8) [in /home/sydney/HeliosOS/app/__init__.py:103]
2025-08-23 22:03:50,506 INFO: OpenAI client initialized successfully [in /home/sydney/HeliosOS/app/enhanced_ai_client.py:49]
2025-08-23 22:03:50,592 ERROR: Failed to create database tables: (psycopg2.OperationalError) connection to server at "localhost" (127.0.0.1), port 5432 failed: Connection refused
	Is the server running on that host and accepting TCP/IP connections?

(Background on this error at: https://sqlalche.me/e/20/e3q8) [in /home/sydney/HeliosOS/app/__init__.py:103]
2025-08-24 00:12:12,582 WARNING: OpenAI API key not found, using fallback methods [in /home/sydney/HeliosOS/app/enhanced_ai_client.py:51]
2025-08-24 00:12:12,679 INFO: Database tables created successfully [in /home/sydney/HeliosOS/app/__init__.py:106]
2025-08-24 00:12:12,679 INFO: AI services initialized [in /home/sydney/HeliosOS/app/__init__.py:136]
2025-08-24 00:12:12,680 INFO: Application manager initialized [in /home/sydney/HeliosOS/app/__init__.py:140]
2025-08-24 00:12:12,680 INFO: Workflow engine initialized [in /home/sydney/HeliosOS/app/__init__.py:144]
2025-08-24 00:12:12,680 INFO: Enhanced AI client initialized [in /home/sydney/HeliosOS/app/__init__.py:148]
2025-08-24 00:14:27,997 INFO: OpenAI client initialized successfully [in /home/sydney/HeliosOS/app/enhanced_ai_client.py:49]
2025-08-24 00:14:28,085 ERROR: Failed to create database tables: (psycopg2.OperationalError) connection to server at "localhost" (127.0.0.1), port 5432 failed: Connection refused
	Is the server running on that host and accepting TCP/IP connections?

(Background on this error at: https://sqlalche.me/e/20/e3q8) [in /home/sydney/HeliosOS/app/__init__.py:112]
2025-08-24 00:17:31,449 INFO: OpenAI client initialized successfully [in /home/sydney/HeliosOS/app/enhanced_ai_client.py:49]
2025-08-24 00:17:31,516 ERROR: Failed to create database tables: (psycopg2.OperationalError) connection to server at "localhost" (127.0.0.1), port 5432 failed: Connection refused
	Is the server running on that host and accepting TCP/IP connections?

(Background on this error at: https://sqlalche.me/e/20/e3q8) [in /home/sydney/HeliosOS/app/__init__.py:112]
2025-08-24 00:17:31,519 WARNING: HuggingFace API key not configured, using fallback summary [in /home/sydney/HeliosOS/app/ai_client.py:81]
2025-08-24 11:27:06,127 INFO: OpenAI client initialized successfully [in /home/sydney/HeliosOS/app/enhanced_ai_client.py:49]
2025-08-24 11:27:06,709 INFO: Database tables created successfully [in /home/sydney/HeliosOS/app/__init__.py:106]
2025-08-24 11:27:06,711 INFO: AI services initialized [in /home/sydney/HeliosOS/app/__init__.py:136]
2025-08-24 11:27:06,711 INFO: Application manager initialized [in /home/sydney/HeliosOS/app/__init__.py:140]
2025-08-24 11:27:06,712 INFO: Workflow engine initialized [in /home/sydney/HeliosOS/app/__init__.py:144]
2025-08-24 11:27:06,712 INFO: Enhanced AI client initialized [in /home/sydney/HeliosOS/app/__init__.py:148]
2025-08-24 11:27:06,831 WARNING: HuggingFace API key not configured, using fallback summary [in /home/sydney/HeliosOS/app/ai_client.py:81]
2025-08-24 12:11:14,524 INFO: OpenAI client initialized successfully [in /home/sydney/HeliosOS/app/enhanced_ai_client.py:49]
2025-08-24 12:11:15,368 INFO: Database tables created successfully [in /home/sydney/HeliosOS/app/__init__.py:106]
2025-08-24 12:11:15,369 INFO: AI services initialized [in /home/sydney/HeliosOS/app/__init__.py:136]
2025-08-24 12:11:15,377 INFO: Application manager initialized [in /home/sydney/HeliosOS/app/__init__.py:140]
2025-08-24 12:11:15,377 INFO: Workflow engine initialized [in /home/sydney/HeliosOS/app/__init__.py:144]
2025-08-24 12:11:15,378 INFO: Enhanced AI client initialized [in /home/sydney/HeliosOS/app/__init__.py:148]
2025-08-24 12:11:46,075 INFO: OpenAI client initialized successfully [in /home/sydney/HeliosOS/app/enhanced_ai_client.py:49]
2025-08-24 12:11:46,336 INFO: Database tables created successfully [in /home/sydney/HeliosOS/app/__init__.py:106]
2025-08-24 12:11:46,337 INFO: AI services initialized [in /home/sydney/HeliosOS/app/__init__.py:136]
2025-08-24 12:11:46,339 INFO: Application manager initialized [in /home/sydney/HeliosOS/app/__init__.py:140]
2025-08-24 12:11:46,339 INFO: Workflow engine initialized [in /home/sydney/HeliosOS/app/__init__.py:144]
2025-08-24 12:11:46,340 INFO: Enhanced AI client initialized [in /home/sydney/HeliosOS/app/__init__.py:148]
2025-08-24 12:11:46,414 WARNING: HuggingFace API key not configured, using fallback summary [in /home/sydney/HeliosOS/app/ai_client.py:81]
2025-08-24 12:15:45,128 INFO: OpenAI client initialized successfully [in /home/sydney/HeliosOS/app/enhanced_ai_client.py:49]
2025-08-24 12:15:45,332 INFO: Database tables created successfully [in /home/sydney/HeliosOS/app/__init__.py:106]
2025-08-24 12:15:45,334 INFO: AI services initialized [in /home/sydney/HeliosOS/app/__init__.py:136]
2025-08-24 12:15:45,334 INFO: Application manager initialized [in /home/sydney/HeliosOS/app/__init__.py:140]
2025-08-24 12:15:45,335 INFO: Workflow engine initialized [in /home/sydney/HeliosOS/app/__init__.py:144]
2025-08-24 12:15:45,335 INFO: Enhanced AI client initialized [in /home/sydney/HeliosOS/app/__init__.py:148]
2025-08-24 12:15:45,488 WARNING: HuggingFace API key not configured, using fallback summary [in /home/sydney/HeliosOS/app/ai_client.py:81]
2025-08-24 12:30:37,635 INFO: OpenAI client initialized successfully [in /home/sydney/HeliosOS/app/enhanced_ai_client.py:49]
2025-08-24 12:30:37,689 INFO: Database tables created successfully [in /home/sydney/HeliosOS/app/__init__.py:108]
2025-08-24 12:30:37,690 INFO: AI services initialized [in /home/sydney/HeliosOS/app/__init__.py:138]
2025-08-24 12:30:37,691 INFO: Application manager initialized [in /home/sydney/HeliosOS/app/__init__.py:142]
2025-08-24 12:30:37,691 INFO: Workflow engine initialized [in /home/sydney/HeliosOS/app/__init__.py:146]
2025-08-24 12:30:37,691 INFO: Enhanced AI client initialized [in /home/sydney/HeliosOS/app/__init__.py:150]
2025-08-24 12:30:37,713 WARNING: HuggingFace API key not configured, using fallback summary [in /home/sydney/HeliosOS/app/ai_client.py:81]
2025-08-24 13:39:41,047 INFO: OpenAI client initialized successfully [in /home/sydney/HeliosOS/app/enhanced_ai_client.py:49]
2025-08-24 13:39:41,225 INFO: Database tables created successfully [in /home/sydney/HeliosOS/app/__init__.py:108]
2025-08-24 13:39:41,226 INFO: AI services initialized [in /home/sydney/HeliosOS/app/__init__.py:138]
2025-08-24 13:39:41,227 INFO: Application manager initialized [in /home/sydney/HeliosOS/app/__init__.py:142]
2025-08-24 13:39:41,227 INFO: Workflow engine initialized [in /home/sydney/HeliosOS/app/__init__.py:146]
2025-08-24 13:39:41,228 INFO: Enhanced AI client initialized [in /home/sydney/HeliosOS/app/__init__.py:150]
2025-08-24 13:39:41,308 WARNING: HuggingFace API key not configured, using fallback summary [in /home/sydney/HeliosOS/app/ai_client.py:81]
2025-08-24 13:53:28,869 INFO: OpenAI client initialized successfully [in /home/sydney/HeliosOS/app/enhanced_ai_client.py:49]
2025-08-24 13:53:28,971 INFO: Database tables created successfully [in /home/sydney/HeliosOS/app/__init__.py:108]
2025-08-24 13:53:28,973 INFO: AI services initialized [in /home/sydney/HeliosOS/app/__init__.py:138]
2025-08-24 13:53:28,973 INFO: Application manager initialized [in /home/sydney/HeliosOS/app/__init__.py:142]
2025-08-24 13:53:28,973 INFO: Workflow engine initialized [in /home/sydney/HeliosOS/app/__init__.py:146]
2025-08-24 13:53:28,973 INFO: Enhanced AI client initialized [in /home/sydney/HeliosOS/app/__init__.py:150]
2025-08-24 13:53:29,004 WARNING: HuggingFace API key not configured, using fallback summary [in /home/sydney/HeliosOS/app/ai_client.py:81]
2025-08-24 14:05:09,715 INFO: OpenAI client initialized successfully [in /home/sydney/HeliosOS/app/enhanced_ai_client.py:49]
2025-08-24 14:05:10,038 INFO: Database tables created successfully [in /home/sydney/HeliosOS/app/__init__.py:108]
2025-08-24 14:05:10,040 INFO: AI services initialized [in /home/sydney/HeliosOS/app/__init__.py:138]
2025-08-24 14:05:10,041 INFO: Application manager initialized [in /home/sydney/HeliosOS/app/__init__.py:142]
2025-08-24 14:05:10,041 INFO: Workflow engine initialized [in /home/sydney/HeliosOS/app/__init__.py:146]
2025-08-24 14:05:10,041 INFO: Enhanced AI client initialized [in /home/sydney/HeliosOS/app/__init__.py:150]
2025-08-24 14:05:10,264 WARNING: HuggingFace API key not configured, using fallback summary [in /home/sydney/HeliosOS/app/ai_client.py:81]
2025-08-24 14:13:12,158 INFO: OpenAI client initialized successfully [in /home/sydney/HeliosOS/app/enhanced_ai_client.py:49]
2025-08-24 14:13:12,474 INFO: Database tables created successfully [in /home/sydney/HeliosOS/app/__init__.py:108]
2025-08-24 14:13:12,475 INFO: AI services initialized [in /home/sydney/HeliosOS/app/__init__.py:138]
2025-08-24 14:13:12,476 INFO: Application manager initialized [in /home/sydney/HeliosOS/app/__init__.py:142]
2025-08-24 14:13:12,476 INFO: Workflow engine initialized [in /home/sydney/HeliosOS/app/__init__.py:146]
2025-08-24 14:13:12,477 INFO: Enhanced AI client initialized [in /home/sydney/HeliosOS/app/__init__.py:150]
2025-08-24 14:13:12,573 WARNING: HuggingFace API key not configured, using fallback summary [in /home/sydney/HeliosOS/app/ai_client.py:81]
2025-08-24 14:13:42,458 INFO: OpenAI client initialized successfully [in /home/sydney/HeliosOS/app/enhanced_ai_client.py:49]
2025-08-24 14:13:42,604 INFO: Database tables created successfully [in /home/sydney/HeliosOS/app/__init__.py:108]
2025-08-24 14:13:42,608 INFO: AI services initialized [in /home/sydney/HeliosOS/app/__init__.py:138]
2025-08-24 14:13:42,608 INFO: Application manager initialized [in /home/sydney/HeliosOS/app/__init__.py:142]
2025-08-24 14:13:42,609 INFO: Workflow engine initialized [in /home/sydney/HeliosOS/app/__init__.py:146]
2025-08-24 14:13:42,610 INFO: Enhanced AI client initialized [in /home/sydney/HeliosOS/app/__init__.py:150]
2025-08-24 14:13:42,652 WARNING: HuggingFace API key not configured, using fallback summary [in /home/sydney/HeliosOS/app/ai_client.py:81]
2025-08-24 14:15:38,692 INFO: OpenAI client initialized successfully [in /home/sydney/HeliosOS/app/enhanced_ai_client.py:49]
2025-08-24 14:15:39,164 INFO: Database tables created successfully [in /home/sydney/HeliosOS/app/__init__.py:108]
2025-08-24 14:15:39,166 INFO: AI services initialized [in /home/sydney/HeliosOS/app/__init__.py:138]
2025-08-24 14:15:39,177 INFO: Application manager initialized [in /home/sydney/HeliosOS/app/__init__.py:142]
2025-08-24 14:15:39,177 INFO: Workflow engine initialized [in /home/sydney/HeliosOS/app/__init__.py:146]
2025-08-24 14:15:39,177 INFO: Enhanced AI client initialized [in /home/sydney/HeliosOS/app/__init__.py:150]
2025-08-24 14:15:39,370 WARNING: HuggingFace API key not configured, using fallback summary [in /home/sydney/HeliosOS/app/ai_client.py:81]
